<?xml version="1.0" encoding="utf-8"?>
<!-- This URDF was automatically created by SolidWorks to URDF Exporter! Originally created by Stephen Brawner (brawner@gmail.com) 
     Commit Version: 1.6.0-1-g15f4949  Build Version: 1.6.7594.29634
     For more information, please see http://wiki.ros.org/sw_urdf_exporter -->
<robot name="twelvedof_new">
  
  <link name="world"/>
    
  <joint name="worldjoint" type="fixed">
    <origin xyz="0 0 0" rpy="0 0 1.5708" />
    <parent link="world" />
    <child link="base_link" />
  </joint>

<!-- FIRST HALF OF ARM -->
  
  <link name="base_link">
    <inertial>
      <origin xyz="0.0082132 0.045573 -4.3895E-09" rpy="0 0 0" />
      <mass value="10" />
      <inertia
        ixx="0.0143561878212777"
        ixy="-0.000435034350132057"
        ixz="1.30220493170942E-09"
        iyy="0.0253036434758205"
        iyz="2.05181848298011E-10"
        izz="0.017604652680288" />
    </inertial>
    <visual>
      <origin xyz="0 0 0" rpy="0 0 0" />
      <geometry>
        <mesh filename="package://project/meshes/base_link.STL" />
      </geometry>
      <material name="">
        <color rgba="0.898039215686275 0.92156862745098 0.929411764705882 1" />
      </material>
    </visual>
    <!--<collision>
      <origin xyz="0 0 0" rpy="0 0 0" />
      <geometry>
        <mesh filename="package://project/meshes/base_link.STL" />
      </geometry>
    </collision>-->
  </link>
  
  <joint name="theta1" type="continuous">
    <origin xyz="0 0 0.05" rpy="1.5707963267949 0 3.14159265358979" />
    <parent link="base_link" />
    <child link="link1" />
    <axis xyz="0 1 0" />
    <dynamics damping="5.0"/>
  </joint>  
  
  <link name="link1">
    <inertial>
      <origin xyz="-3.4183E-08 0.34451 0.010144" rpy="0 0 0" />
      <mass value="0.1" />
      <inertia
        ixx="0.280533282193697"
        ixy="2.88502865128486E-08"
        ixz="5.12746353903742E-09"
        iyy="0.0214809674041822"
        iyz="-0.0162186945928484"
        izz="0.281062502247758" />
    </inertial>
    <visual>
      <origin xyz="0 0 0" rpy="0 0 0" />
      <geometry>
        <mesh filename="package://project/meshes/link1.STL" />
      </geometry>
      <material name="">
        <color rgba="0.792156862745098 0.819607843137255 0.933333333333333 1" />
      </material>
    </visual>
    <!--<collision>
      <origin xyz="0 0 0" rpy="0 0 0" />
      <geometry>
        <mesh filename="package://project/meshes/link1.STL" />
      </geometry>
    </collision>-->
  </link>
  
  <joint name="theta2" type="continuous">
    <origin xyz="0 0.55 0" rpy="-3.14159265358979 -1.5707963267949 0" />
    <parent link="link1" />
    <child link="link2" />
    <axis xyz="1 0 0" />
    <dynamics damping="5.0"/>
  </joint>
  
  <link name="link2">
    <inertial>
      <origin xyz="-0.099044 -1.7117E-08 0.19438" rpy="0 0 0" />
      <mass value="0.1" />
      <inertia
        ixx="0.128935545829528"
        ixy="-3.59276704863955E-09"
        ixz="0.00824538218148109"
        iyy="0.12959303076696"
        iyz="3.7662632051646E-08"
        izz="0.00894193356578435" />
    </inertial>
    <visual>
      <origin xyz="0 0 0" rpy="0 0 0" />
      <geometry>
        <mesh filename="package://project/meshes/link2.STL" />
      </geometry>
      <material name="">
        <color rgba="0.792156862745098 0.819607843137255 0.933333333333333 1" />
      </material>
    </visual>
    <!--<collision>
      <origin xyz="0 0 0" rpy="0 0 0" />
      <geometry>
        <mesh filename="package://project/meshes/link2.STL" />
      </geometry>
    </collision>-->
  </link>
    
  <joint name="theta3" type="continuous">
    <origin xyz="0 0 0.4" rpy="0 0 3.14159265358979" />
    <parent link="link2" />
    <child link="link3" />
    <axis xyz="1 0 0" />
    <dynamics damping="1.0"/>
  </joint>
  
  
  <link name="link3">
    <inertial>
      <origin xyz="0.011754 -0.069273 -1.9906E-07" rpy="0 0 0" />
      <mass value="0.1" />
      <inertia
        ixx="0.0152262508313679"
        ixy="-0.000252854197484628"
        ixz="-7.59437820571953E-09"
        iyy="0.00238432715240219"
        iyz="-6.63655998102174E-09"
        izz="0.0150750345051429" />
    </inertial>
    <visual>
      <origin xyz="0 0 0" rpy="0 0 0" />
      <geometry>
        <mesh filename="package://project/meshes/link3.STL" />
      </geometry>
      <material name="">
        <color rgba="0.792156862745098 0.819607843137255 0.933333333333333 1" />
      </material>
    </visual>
    <!--<collision>
      <origin xyz="0 0 0" rpy="0 0 0" />
      <geometry>
        <mesh filename="package://project/meshes/link3.STL" />
      </geometry>
    </collision>-->
  </link>
  
  <joint name="theta4" type="continuous">
    <origin xyz="0.00999999999999997 -0.156 0" rpy="3.14159265358979 -3.14159265358979 3.14159265358979" />
    <parent link="link3" />
    <child link="link4" />
    <axis xyz="0 1 0" />
    <dynamics damping="0.2"/>
  </joint>
  
  <link name="link4">
    <inertial>
      <origin xyz="-2.423E-05 -0.13288 0.010643" rpy="0 3.14159265358979 0" />
      <mass value="0.1" />
      <inertia
        ixx="0.00652454443000916"
        ixy="-2.63113923987127E-06"
        ixz="1.4312330638641E-06"
        iyy="0.00162842387868455"
        iyz="0.00113452921322352"
        izz="0.00559173664508866" />
    </inertial>
    <visual>
      <origin xyz="0 0 0" rpy="0 3.14159265358979 0" />
      <geometry>
        <mesh filename="package://project/meshes/link4.STL" />
      </geometry>
      <material name="">
        <color rgba="0.792156862745098 0.819607843137255 0.933333333333333 1" />
      </material>
    </visual>
    <!--<collision>
      <origin xyz="0 0 0" rpy="0 3.14159265358979 0" />
      <geometry>
        <mesh filename="package://project/meshes/link4.STL" />
      </geometry>
    </collision>-->
  </link>
  
  <joint name="theta5" type="continuous">
    <origin xyz="-0.000158056929492672 -0.244 0" rpy="-1.5707963267949 0 3.14159265358979" />
    <parent link="link4" />
    <child link="link5" />
    <axis xyz="0 1 0" />
    <dynamics damping="0.2"/>
  </joint>
  
  <link name="link5">
    <inertial>
      <origin xyz="-8.5927E-06 2.9948E-09 0" rpy="0 0 0" />
      <mass value="0.1" />
      <inertia
        ixx="0.000268508912730322"
        ixy="-1.05404001827445E-14"
        ixz="2.8134907313249E-12"
        iyy="0.000445501225998283"
        iyz="-4.09234992736264E-12"
        izz="0.000491869576064115" />
    </inertial>
    <visual>
      <origin xyz="0 0 0" rpy="0 0 0" />
      <geometry>
        <mesh filename="package://project/meshes/link5.STL" />
      </geometry>
      <material name="">
        <color rgba="0.792156862745098 0.819607843137255 0.933333333333333 1" />
      </material>
    </visual>
    <!--<collision>
      <origin xyz="0 0 0" rpy="0 0 0" />
      <geometry>
        <mesh filename="package://project/meshes/link5.STL" />
      </geometry>
    </collision>-->
  </link>

  <joint name="theta6" type="continuous">
    <origin xyz="0 0 0" rpy="3.1416 -1.5708 0" />
    <parent link="link5" />
    <child link="link6" />
    <axis xyz="0 0 1" />
    <dynamics damping="0.2"/>
  </joint>

  <link name="link6">
    <inertial>
      <origin xyz="0.0051917 0.2733 -0.0049985" rpy="0 0 0" />
      <mass value="0.1" />
      <inertia
        ixx="0.0522030439082721"
        ixy="-0.00158209475866237"
        ixz="-6.38836647121218E-05"
        iyy="0.00450482103345596"
        iyz="-0.00340305922390723"
        izz="0.0501774844868825" />
    </inertial>
    <visual>
      <origin xyz="0 0 0" rpy="0 0 0" />
      <geometry>
        <mesh filename="package://project/meshes/link6.STL" />
      </geometry>
      <material name="">
        <color rgba="0.792156862745098 0.819607843137255 0.933333333333333 1" />
      </material>
    </visual>
    <!--<collision>
      <origin xyz="0 0 0" rpy="0 0 0" />
      <geometry>
        <mesh filename="package://project/meshes/link6.STL" />
      </geometry>
    </collision>-->
  </link>

  <joint name="final1" type="fixed">
    <parent link="link6"/>
    <child  link="tip_elbow"/>
    <origin xyz="0 0.2 0.1" rpy="1.5708 0 -1.5708"/>
  </joint>

  <link name="tip_elbow"/>
  
 
 <!-- SECOND HALF OF ARM -->

  <joint name="theta7" type="continuous">
    <origin xyz="0 0.4 0" rpy="1.5707963267949 -1.5707963267949 0" />
    <parent link="link6" />
    <child link="link7" />
    <axis xyz="0 1 0" />
    <dynamics damping="0.2"/>
  </joint>

  <link name="link7">
    <inertial>
      <origin xyz="0.0044934 0.36072 6.8848E-09" rpy="0 0 0" />
      <mass value="0.1" />
      <inertia
        ixx="0.120977117963601"
        ixy="-0.00358173551662174"
        ixz="-1.92392938248504E-09"
        iyy="0.00427523422420143"
        iyz="-2.98092198286552E-09"
        izz="0.120860768990603" />
    </inertial>
    <visual>
      <origin xyz="0 0 0" rpy="0 0 0" />
      <geometry>
        <mesh filename="package://project/meshes/link7.STL" />
      </geometry>
      <material name="">
        <color rgba="0.792156862745098 0.819607843137255 0.933333333333333 1" />
      </material>
    </visual>
    <!--<collision>
      <origin xyz="0 0 0" rpy="0 0 0" />
      <geometry>
        <mesh filename="package://project/meshes/link7.STL" />
      </geometry>
    </collision>-->
  </link>

  <joint name="theta8" type="continuous">
    <origin xyz="0 0.6 0" rpy="0 0 3.14159265358979" />
    <parent link="link7" />
    <child link="link8" />
    <axis xyz="1 0 0" />
    <dynamics damping="5.0"/>
  </joint>
  
  <link name="link8">
    <inertial>
      <origin xyz="0.087875 -1.7703E-08 -0.22474" rpy="0 0 0" />
      <mass value="0.1" />
      <inertia
        ixx="0.0796551330078775"
        ixy="5.6504092407821E-09"
        ixz="0.00748044758508915"
        iyy="0.0813191685089296"
        iyz="5.4244447681561E-09"
        izz="0.00490675543598511" />
    </inertial>
    <visual>
      <origin xyz="0 0 0" rpy="0 0 0" />
      <geometry>
        <mesh filename="package://project/meshes/link8.STL" />
      </geometry>
      <material name="">
        <color rgba="0.792156862745098 0.819607843137255 0.933333333333333 1" />
      </material>
    </visual>
    <!--<collision>
      <origin xyz="0 0 0" rpy="0 0 0" />
      <geometry>
        <mesh filename="package://project/meshes/link8.STL" />
      </geometry>
    </collision>-->
  </link>

  <joint name="theta9" type="continuous">
    <origin xyz="0 0 -0.4" rpy="-3.14159263868864 0 0" />
    <parent link="link8" />
    <child link="link9" />
    <axis xyz="1 0 0" />
    <dynamics damping="1.0"/>
  </joint>


  <link name="link9">
    <inertial>
      <origin xyz="0.0066483 -0.12042 -2.4888E-07" rpy="0 0 0" />
      <mass value="0.1" />
      <inertia
        ixx="0.0114050795265076"
        ixy="-0.0002365697800322"
        ixz="-3.38034585685076E-09"
        iyy="0.00148310827639032"
        iyz="-3.64333100183754E-09"
        izz="0.0113333864819022" />
    </inertial>
    <visual>
      <origin xyz="0 0 0" rpy="0 0 0" />
      <geometry>
        <mesh filename="package://project/meshes/link9.STL" />
      </geometry>
      <material name="">
        <color rgba="0.792156862745098 0.819607843137255 0.933333333333333 1" />
      </material>
    </visual>
    <!--<collision>
      <origin xyz="0 0 0" rpy="0 0 0" />
      <geometry>
        <mesh filename="package://project/meshes/link9.STL" />
      </geometry>
    </collision>-->
  </link>

  <joint name="theta10" type="continuous">
    <origin xyz="0.005 -0.26 0" rpy="3.14159265358979 0 3.14159265358979" />
    <parent link="link9" />
    <child link="link10" />
    <axis xyz="0 1 0" />
    <dynamics damping="0.2"/>
  </joint>

  <link name="link10">
    <inertial>
      <origin xyz="-2.3404E-05 -0.18747 0.0085476" rpy="0 0 0" />
      <mass value="0.1" />
      <inertia
        ixx="0.00624074124214675"
        ixy="-2.56275777992662E-06"
        ixz="1.42191262724024E-06"
        iyy="0.00153442214771151"
        iyz="0.00110450946529512"
        izz="0.00531178670708837" />
    </inertial>
    <visual>
      <origin xyz="0 0 0" rpy="0 0 0" />
      <geometry>
        <mesh filename="package://project/meshes/link10.STL" />
      </geometry>
      <material name="">
        <color rgba="0.792156862745098 0.819607843137255 0.933333333333333 1" />
      </material>
    </visual>
    <!--<collision>
      <origin xyz="0 0 0" rpy="0 0 0" />
      <geometry>
        <mesh filename="package://project/meshes/link10.STL" />
      </geometry>
    </collision>-->
  </link>

  <joint name="theta11" type="continuous">
    <origin xyz="-0.000158056929492617 -0.34 0" rpy="-1.5707963267949 0 3.14159265358979" />
    <parent link="link10" />
    <child link="link11" />
    <axis xyz="0 1 0" />
    <dynamics damping="0.2"/>
  </joint>

  <link name="link11">
    <inertial>
      <origin xyz="-2.0264E-05 9.9734E-09 -9.1441E-08" rpy="0 0 0" />
      <mass value="0.1" />
      <inertia
        ixx="0.000268508912730321"
        ixy="1.05404015773174E-14"
        ixz="-2.81349071030043E-12"
        iyy="0.000445501225998283"
        iyz="-4.09234984570201E-12"
        izz="0.000491869576064114" />
    </inertial>
    <visual>
      <origin xyz="0 0 0" rpy="0 0 0" />
      <geometry>
        <mesh filename="package://project/meshes/link11.STL" />
      </geometry>
      <material name="">
        <color rgba="0.792156862745098 0.819607843137255 0.933333333333333 1" />
      </material>
    </visual>
    <!--<collision>
      <origin xyz="0 0 0" rpy="0 0 0" />
      <geometry>
        <mesh filename="package://project/meshes/link11.STL" />
      </geometry>
    </collision>-->
  </link>

  <joint name="theta12" type="continuous">
    <origin xyz="0 0 0" rpy="0 1.5707963267949 0" />
    <parent link="link11" />
    <child link="link12" />
    <axis xyz="0 0 1" />
    <dynamics damping="0.2"/>
  </joint>

  <link name="link12">
    <inertial>
      <origin xyz="-2.9191E-07 0.031037 0.029216" rpy="0 0 0" />
      <mass value="0.1" />
      <inertia
        ixx="0.00449686744365017"
        ixy="-5.41238637157819E-09"
        ixz="3.66408930129254E-09"
        iyy="0.00184883163621398"
        iyz="0.00108407821056809"
        izz="0.00322066196867968" />
    </inertial>
    <visual>
      <origin xyz="0 0 0" rpy="0 0 0" />
      <geometry>
        <mesh filename="package://project/meshes/link12.STL" />
      </geometry>
      <material name="">
        <color rgba="0.792156862745098 0.819607843137255 0.933333333333333 1" />
      </material>
    </visual>
    <!--<collision>
      <origin xyz="0 0 0" rpy="0 0 0" />
      <geometry>
        <mesh filename="package://project/meshes/link12.STL" />
      </geometry>
    </collision>-->
  </link>

  <joint name="final2" type="fixed">
    <parent link="link12"/>
    <child  link="tip_full"/>
    <origin xyz="0 0.1 0" rpy="0 -1.5708 0"/>
  </joint>

  <link name="tip_full"/>













  <!-- *************************************************** -->
  <!-- ****** Building Blocks (Visual AND Inertial) ****** -->
  <!-- *************************************************** -->

  <!-- *** base_link-Fixed: Mount 1, Motor 1 *** -->

  <joint name="attach-mount1" type="fixed">
    <parent link="base_link"/>
    <child  link="mount1"/>
  </joint>
  <link name="mount1">
    <visual>
      <origin xyz="0 0 0.05" rpy="0 0 0"/>
      <geometry>
  <cylinder length="0.1" radius="0.011"/>
      </geometry>
      <material name="black"/>
    </visual>
    <collision>
      <origin xyz="0 0 0.05" rpy="0 0 0"/>
      <geometry>
  <cylinder length="0.1" radius="0.011"/>
      </geometry>
    </collision>
    <inertial>
      <origin xyz="0 0 0.05" rpy="0 0 0"/>
      <mass value="0.2"/>
      <inertia
        ixx="0.000687" ixy="0.0" ixz="0.0"
        iyy="0.000687" iyz="0.0"
        izz="1.000040"/>
    </inertial>
  </link>

  <joint name="attach-motor1" type="fixed">
    <parent link="base_link"/>
    <child  link="motor1"/>
  </joint>
  <link name="motor1">
    <visual>
      <origin xyz="0 0 0.05" rpy="0 0 0"/>
      <geometry>
  <cylinder length="0.1" radius="0.02"/>
      </geometry>
      <material name="gray"/>
    </visual>
    <collision>
      <origin xyz="0 0 0.05" rpy="0 0 0"/>
      <geometry>
  <cylinder length="0.1" radius="0.02"/>
      </geometry>
    </collision>
    <inertial>
      <origin xyz="0 0 0.05" rpy="0 0 0"/>
      <mass value="0.4"/>
      <inertia
        ixx="0.500990" ixy="0.0" ixz="0.0"
        iyy="0.000990" iyz="0.0"
        izz="0.000313"/>
    </inertial>
  </link>


  <!-- *** Motor 1 Output: Mount 2, Motor 2 *** -->

  <joint name="attach-mount2" type="fixed">
    <parent link="link1"/>
    <child  link="mount2"/>
  </joint>
  <link name="mount2">
    <visual>
      <origin xyz="0 0.55 0" rpy="0 0 -1.5708"/>
      <geometry>
  <cylinder length="0.1" radius="0.005"/>
      </geometry>
      <material name="black"/>
    </visual>
    <collision>
      <origin xyz="0 0.55 0" rpy="0 0 -1.5708"/>
      <geometry>
  <cylinder length="0.1" radius="0.005"/>
      </geometry>
    </collision>
    <inertial>
      <origin xyz="0 0.55 0" rpy="0 0 -1.5708"/>
      <mass value="0.2"/>
      <inertia
        ixx="0.000687" ixy="0.0" ixz="0.0"
        iyy="0.000687" iyz="0.0"
        izz="1.000040"/>
    </inertial>
  </link>

  <joint name="attach-motor2" type="fixed">
    <parent link="link1"/>
    <child  link="motor2"/>
  </joint>
  <link name="motor2">
    <visual>
      <origin xyz="0 0.55 0" rpy="0 0 -1.5708"/>
      <geometry>
  <cylinder length="0.1" radius="0.011"/>
      </geometry>
      <material name="gray"/>
    </visual>
    <collision>
      <origin xyz="0 0.55 0" rpy="0 0 -1.5708"/>
      <geometry>
  <cylinder length="0.1" radius="0.011"/>
      </geometry>
    </collision>
    <inertial>
      <origin xyz="0 0.55 0" rpy="0 0 -1.5708"/>
      <mass value="0.4"/>
      <inertia
        ixx="0.500990" ixy="0.0" ixz="0.0"
        iyy="0.000990" iyz="0.0"
        izz="0.000313"/>
    </inertial>
  </link>


  <!-- *** Motor 2 Output: Mount 3, Motor 3 *** -->

  <joint name="attach-mount3" type="fixed">
    <parent link="link2"/>
    <child  link="mount3"/>
  </joint>
  <link name="mount3">
    <visual>
      <origin xyz="0 0 0.4" rpy="0 -1.5708 0"/>
      <geometry>
  <cylinder length="0.1" radius="0.005"/>
      </geometry>
      <material name="black"/>
    </visual>
    <collision>
      <origin xyz="0 0 0.4" rpy="0 -1.5708 0"/>
      <geometry>
  <cylinder length="0.1" radius="0.005"/>
      </geometry>
    </collision>
    <inertial>
      <origin xyz="0 0 0.4" rpy="0 -1.5708 0"/>
      <mass value="0.2"/>
      <inertia
        ixx="0.000687" ixy="0.0" ixz="0.0"
        iyy="0.000687" iyz="0.0"
        izz="1.000040"/>
    </inertial>
  </link>

  <joint name="attach-motor3" type="fixed">
    <parent link="link2"/>
    <child  link="motor3"/>
  </joint>
  <link name="motor3">
    <visual>
      <origin xyz="0 0 0.4" rpy="0 -1.5708 0"/>
      <geometry>
  <cylinder length="0.1" radius="0.011"/>
      </geometry>
      <material name="gray"/>
    </visual>
    <collision>
      <origin xyz="0 0 0.4" rpy="0 -1.5708 0"/>
      <geometry>
  <cylinder length="0.1" radius="0.011"/>
      </geometry>
    </collision>
    <inertial>
      <origin xyz="0 0 0.4" rpy="0 -1.5708 0"/>
      <mass value="0.4"/>
      <inertia
        ixx="0.500990" ixy="0.0" ixz="0.0"
        iyy="0.000990" iyz="0.0"
        izz="0.000313"/>
    </inertial>
  </link>


  <!-- *** Motor 3 Output: Mount 4, Motor 4 *** -->

  <joint name="attach-mount4" type="fixed">
    <parent link="link3"/>
    <child  link="mount4"/>
  </joint>
  <link name="mount4">
    <visual>
      <origin xyz="0.00999999999999997 -0.156 0" rpy="-1.5708 0 0"/>
      <geometry>
  <cylinder length="0.1" radius="0.005"/>
      </geometry>
      <material name="black"/>
    </visual>
    <collision>
      <origin xyz="0.00999999999999997 -0.156 0" rpy="-1.5708 0 0"/>
      <geometry>
  <cylinder length="0.1" radius="0.005"/>
      </geometry>
    </collision>
    <inertial>
      <origin xyz="0.00999999999999997 -0.156 0" rpy="-1.5708 0 0"/>
      <mass value="0.2"/>
      <inertia
        ixx="0.000687" ixy="0.0" ixz="0.0"
        iyy="0.000687" iyz="0.0"
        izz="1.000040"/>
    </inertial>
  </link>

  <joint name="attach-motor4" type="fixed">
    <parent link="link3"/>
    <child  link="motor4"/>
  </joint>
  <link name="motor4">
    <visual>
      <origin xyz="0.00999999999999997 -0.156 0" rpy="-1.5708 0 0"/>
      <geometry>
  <cylinder length="0.1" radius="0.011"/>
      </geometry>
      <material name="gray"/>
    </visual>
    <collision>
      <origin xyz="0.00999999999999997 -0.156 0" rpy="-1.5708 0 0"/>
      <geometry>
  <cylinder length="0.1" radius="0.011"/>
      </geometry>
    </collision>
    <inertial>
      <origin xyz="0.00999999999999997 -0.156 0" rpy="-1.5708 0 0"/>
      <mass value="1.5"/>
      <inertia
        ixx="0.500990" ixy="0.0" ixz="0.0"
        iyy="0.000990" iyz="0.0"
        izz="0.000313"/>
    </inertial>
  </link>


  <!-- *** Motor 4 Output: Mount 5, Motor 5 *** -->

  <joint name="attach-mount5" type="fixed">
    <parent link="link4"/>
    <child  link="mount5"/>
  </joint>
  <link name="mount5">
    <visual>
      <origin xyz="-0.000158056929492672 -0.244 0" rpy="0 0 -1.5708"/>
      <geometry>
  <cylinder length="0.1" radius="0.005"/>
      </geometry>
      <material name="black"/>
    </visual>
    <collision>
      <origin xyz="-0.000158056929492672 -0.244 0" rpy="0 0 -1.5708"/>
      <geometry>
  <cylinder length="0.1" radius="0.005"/>
      </geometry>
    </collision>
    <inertial>
      <origin xyz="-0.000158056929492672 -0.244 0" rpy="0 0 -1.5708"/>
      <mass value="0.2"/>
      <inertia
        ixx="0.000687" ixy="0.0" ixz="0.0"
        iyy="0.000687" iyz="0.0"
        izz="1.000040"/>
    </inertial>
  </link>

  <joint name="attach-motor5" type="fixed">
    <parent link="link4"/>
    <child  link="motor5"/>
  </joint>
  <link name="motor5">
    <visual>
      <origin xyz="-0.000158056929492672 -0.244 0" rpy="0 0 -1.5708"/>
      <geometry>
  <cylinder length="0.1" radius="0.011"/>
      </geometry>
      <material name="gray"/>
    </visual>
    <collision>
      <origin xyz="-0.000158056929492672 -0.244 0" rpy="0 0 -1.5708"/>
      <geometry>
  <cylinder length="0.1" radius="0.011"/>
      </geometry>
    </collision>
    <inertial>
      <origin xyz="-0.000158056929492672 -0.244 0" rpy="0 0 -1.5708"/>
      <mass value="1.5"/>
      <inertia
        ixx="0.500990" ixy="0.0" ixz="0.0"
        iyy="0.000990" iyz="0.0"
        izz="0.000313"/>
    </inertial>
  </link>


  <!-- *** Motor 5 Output: Mount 6, Motor 6 *** -->

  <joint name="attach-mount6" type="fixed">
    <parent link="link5"/>
    <child  link="mount6"/>
  </joint>
  <link name="mount6">
    <visual>
      <origin xyz="0 0 0" rpy="3.1416 -1.5708 0"/>
      <geometry>
  <cylinder length="0.1" radius="0.005"/>
      </geometry>
      <material name="black"/>
    </visual>
    <collision>
      <origin xyz="0 0 0" rpy="3.1416 -1.5708 0"/>
      <geometry>
  <cylinder length="0.1" radius="0.005"/>
      </geometry>
    </collision>
    <inertial>
      <origin xyz="0 0 0" rpy="3.1416 -1.5708 0"/>
      <mass value="0.2"/>
      <inertia
        ixx="0.000687" ixy="0.0" ixz="0.0"
        iyy="0.000687" iyz="0.0"
        izz="1.000040"/>
    </inertial>
  </link>

  <joint name="attach-motor6" type="fixed">
    <parent link="link5"/>
    <child  link="motor6"/>
  </joint>
  <link name="motor6">
    <visual>
      <origin xyz="0 0 0" rpy="3.1416 -1.5708 0"/>
      <geometry>
  <cylinder length="0.1" radius="0.011"/>
      </geometry>
      <material name="gray"/>
    </visual>
    <collision>
      <origin xyz="0 0 0" rpy="3.1416 -1.5708 0"/>
      <geometry>
  <cylinder length="0.1" radius="0.011"/>
      </geometry>
    </collision>
    <inertial>
      <origin xyz="0 0 0" rpy="3.1416 -1.5708 0"/>
      <mass value="1.5"/>
      <inertia
        ixx="0.500990" ixy="0.0" ixz="0.0"
        iyy="0.000990" iyz="0.0"
        izz="0.000313"/>
    </inertial>
  </link>


  <!-- *** Motor 6 Output: Mount 7, Motor 7 *** -->

  <joint name="attach-mount7" type="fixed">
    <parent link="link6"/>
    <child  link="mount7"/>
  </joint>
  <link name="mount7">
    <visual>
      <origin xyz="0 0.4 0" rpy="0 1.5708 0"/>
      <geometry>
  <cylinder length="0.1" radius="0.005"/>
      </geometry>
      <material name="black"/>
    </visual>
    <collision>
      <origin xyz="0 0.4 0" rpy="0 1.5708 0"/>
      <geometry>
  <cylinder length="0.1" radius="0.005"/>
      </geometry>
    </collision>
    <inertial>
      <origin xyz="0 0.4 0" rpy="0 1.5708 0"/>
      <mass value="0.2"/>
      <inertia
        ixx="0.000687" ixy="0.0" ixz="0.0"
        iyy="0.000687" iyz="0.0"
        izz="1.000040"/>
    </inertial>
  </link>

  <joint name="attach-motor7" type="fixed">
    <parent link="link6"/>
    <child  link="motor7"/>
  </joint>
  <link name="motor7">
    <visual>
      <origin xyz="0 0.4 0" rpy="0 1.5708 0"/>
      <geometry>
  <cylinder length="0.1" radius="0.011"/>
      </geometry>
      <material name="gray"/>
    </visual>
    <collision>
      <origin xyz="0 0.4 0" rpy="0 1.5708 0"/>
      <geometry>
  <cylinder length="0.1" radius="0.011"/>
      </geometry>
    </collision>
    <inertial>
      <origin xyz="0 0.4 0" rpy="0 1.5708 0"/>
      <mass value="1.5"/>
      <inertia
        ixx="0.500990" ixy="0.0" ixz="0.0"
        iyy="0.000990" iyz="0.0"
        izz="0.000313"/>
    </inertial>
  </link>


  <!-- *** Motor 7 Output: Mount 8, Motor 8 *** -->

  <joint name="attach-mount8" type="fixed">
    <parent link="link7"/>
    <child  link="mount8"/>
  </joint>
  <link name="mount8">
    <visual>
      <origin xyz="0 0.6 0" rpy="0 1.5708 0"/>
      <geometry>
  <cylinder length="0.1" radius="0.005"/>
      </geometry>
      <material name="black"/>
    </visual>
    <collision>
      <origin xyz="0 0.6 0" rpy="0 1.5708 0"/>
      <geometry>
  <cylinder length="0.1" radius="0.005"/>
      </geometry>
    </collision>
    <inertial>
      <origin xyz="0 0.6 0" rpy="0 1.5708 0"/>
      <mass value="0.2"/>
      <inertia
        ixx="0.000687" ixy="0.0" ixz="0.0"
        iyy="0.000687" iyz="0.0"
        izz="1.000040"/>
    </inertial>
  </link>

  <joint name="attach-motor8" type="fixed">
    <parent link="link7"/>
    <child  link="motor8"/>
  </joint>
  <link name="motor8">
    <visual>
      <origin xyz="0 0.6 0" rpy="0 1.5708 0"/>
      <geometry>
  <cylinder length="0.1" radius="0.011"/>
      </geometry>
      <material name="gray"/>
    </visual>
    <collision>
      <origin xyz="0 0.6 0" rpy="0 1.5708 0"/>
      <geometry>
  <cylinder length="0.1" radius="0.011"/>
      </geometry>
    </collision>
    <inertial>
      <origin xyz="0 0.6 0" rpy="0 1.5708 0"/>
      <mass value="1.0"/>
      <inertia
        ixx="0.500990" ixy="0.0" ixz="0.0"
        iyy="0.000990" iyz="0.0"
        izz="0.000313"/>
    </inertial>
  </link>


  <!-- *** Motor 8 Output: Mount 9, Motor 9 *** -->

  <joint name="attach-mount9" type="fixed">
    <parent link="link8"/>
    <child  link="mount9"/>
  </joint>
  <link name="mount9">
    <visual>
      <origin xyz="0 0 -0.4" rpy="0 -1.5708 0"/>
      <geometry>
  <cylinder length="0.1" radius="0.005"/>
      </geometry>
      <material name="black"/>
    </visual>
    <collision>
      <origin xyz="0 0 -0.4" rpy="0 -1.5708 0"/>
      <geometry>
  <cylinder length="0.1" radius="0.005"/>
      </geometry>
    </collision>
    <inertial>
      <origin xyz="0 0 -0.4" rpy="0 -1.5708 0"/>
      <mass value="0.2"/>
      <inertia
        ixx="0.000687" ixy="0.0" ixz="0.0"
        iyy="0.000687" iyz="0.0"
        izz="1.000040"/>
    </inertial>
  </link>

  <joint name="attach-motor9" type="fixed">
    <parent link="link8"/>
    <child  link="motor9"/>
  </joint>
  <link name="motor9">
    <visual>
      <origin xyz="0 0 -0.4" rpy="0 -1.5708 0"/>
      <geometry>
  <cylinder length="0.1" radius="0.011"/>
      </geometry>
      <material name="gray"/>
    </visual>
    <collision>
      <origin xyz="0.005 0 -0.4" rpy="0 -1.5708 0"/>
      <geometry>
  <cylinder length="0.1" radius="0.011"/>
      </geometry>
    </collision>
    <inertial>
      <origin xyz="0 0 -0.4" rpy="0 -1.5708 0"/>
      <mass value="1.0"/>
      <inertia
        ixx="0.500990" ixy="0.0" ixz="0.0"
        iyy="0.000990" iyz="0.0"
        izz="0.000313"/>
    </inertial>
  </link>


  <!-- *** Motor 9 Output: Mount 10, Motor 10 *** -->

  <joint name="attach-mount10" type="fixed">
    <parent link="link9"/>
    <child  link="mount10"/>
  </joint>
  <link name="mount10">
    <visual>
      <origin xyz="0.005 -0.26 0" rpy="-1.5708 0 0"/>
      <geometry>
  <cylinder length="0.1" radius="0.005"/>
      </geometry>
      <material name="black"/>
    </visual>
    <collision>
      <origin xyz="0.005 -0.26 0" rpy="-1.5708 0 0"/>
      <geometry>
  <cylinder length="0.1" radius="0.005"/>
      </geometry>
    </collision>
    <inertial>
      <origin xyz="0.005 -0.26 0" rpy="-1.5708 0 0"/>
      <mass value="0.2"/>
      <inertia
        ixx="0.000687" ixy="0.0" ixz="0.0"
        iyy="0.000687" iyz="0.0"
        izz="1.000040"/>
    </inertial>
  </link>

  <joint name="attach-motor10" type="fixed">
    <parent link="link9"/>
    <child  link="motor10"/>
  </joint>
  <link name="motor10">
    <visual>
      <origin xyz="0.005 -0.26 0" rpy="-1.5708 0 0"/>
      <geometry>
  <cylinder length="0.1" radius="0.011"/>
      </geometry>
      <material name="gray"/>
    </visual>
    <collision>
      <origin xyz="0.005 -0.26 0" rpy="-1.5708 0 0"/>
      <geometry>
  <cylinder length="0.1" radius="0.011"/>
      </geometry>
    </collision>
    <inertial>
      <origin xyz="0.005 -0.26 0" rpy="-1.5708 0 0"/>
      <mass value="1.0"/>
      <inertia
        ixx="0.500990" ixy="0.0" ixz="0.0"
        iyy="0.000990" iyz="0.0"
        izz="0.000313"/>
    </inertial>
  </link>


  <!-- *** Motor 10 Output: Mount 11, Motor 11 *** -->

  <joint name="attach-mount11" type="fixed">
    <parent link="link10"/>
    <child  link="mount11"/>
  </joint>
  <link name="mount11">
    <visual>
      <origin xyz="0.000158056929492617 -0.34 0" rpy="0 0 -1.5708"/>
      <geometry>
  <cylinder length="0.1" radius="0.005"/>
      </geometry>
      <material name="black"/>
    </visual>
    <collision>
      <origin xyz="0.000158056929492617 -0.34 0" rpy="0 0 -1.5708"/>
      <geometry>
  <cylinder length="0.1" radius="0.005"/>
      </geometry>
    </collision>
    <inertial>
      <origin xyz="0.000158056929492617 -0.34 0" rpy="0 0 -1.5708"/>
      <mass value="0.2"/>
      <inertia
        ixx="0.000687" ixy="0.0" ixz="0.0"
        iyy="0.000687" iyz="0.0"
        izz="1.000040"/>
    </inertial>
  </link>

  <joint name="attach-motor11" type="fixed">
    <parent link="link10"/>
    <child  link="motor11"/>
  </joint>
  <link name="motor11">
    <visual>
      <origin xyz="0.000158056929492617 -0.34 0" rpy="0 0 -1.5708"/>
      <geometry>
  <cylinder length="0.1" radius="0.011"/>
      </geometry>
      <material name="gray"/>
    </visual>
    <collision>
      <origin xyz="0.000158056929492617 -0.34 0" rpy="0 0 -1.5708"/>
      <geometry>
  <cylinder length="0.1" radius="0.011"/>
      </geometry>
    </collision>
    <inertial>
      <origin xyz="0.000158056929492617 -0.34 0" rpy="0 0 -1.5708"/>
      <mass value="1.0"/>
      <inertia
        ixx="0.500990" ixy="0.0" ixz="0.0"
        iyy="0.000990" iyz="0.0"
        izz="0.000313"/>
    </inertial>
  </link>


  <!-- *** Motor 11 Output: Mount 12, Motor 12 *** -->

  <joint name="attach-mount12" type="fixed">
    <parent link="link11"/>
    <child  link="mount12"/>
  </joint>
  <link name="mount12">
    <visual>
      <origin xyz="0 0 0" rpy="3.1416 -1.5708 0"/>
      <geometry>
  <cylinder length="0.1" radius="0.005"/>
      </geometry>
      <material name="black"/>
    </visual>
    <collision>
      <origin xyz="0 0 0" rpy="3.1416 -1.5708 0"/>
      <geometry>
  <cylinder length="0.1" radius="0.005"/>
      </geometry>
    </collision>
    <inertial>
      <origin xyz="0 0 0" rpy="3.1416 -1.5708 0"/>
      <mass value="0.2"/>
      <inertia
        ixx="0.000687" ixy="0.0" ixz="0.0"
        iyy="0.000687" iyz="0.0"
        izz="1.000040"/>
    </inertial>
  </link>

  <joint name="attach-motor12" type="fixed">
    <parent link="link11"/>
    <child  link="motor12"/>
  </joint>
  <link name="motor12">
    <visual>
      <origin xyz="0 0 0" rpy="3.1416 -1.5708 0"/>
      <geometry>
  <cylinder length="0.1" radius="0.011"/>
      </geometry>
      <material name="gray"/>
    </visual>
    <collision>
      <origin xyz="0 0 0" rpy="3.1416 -1.5708 0"/>
      <geometry>
  <cylinder length="0.1" radius="0.011"/>
      </geometry>
    </collision>
    <inertial>
      <origin xyz="0 0 0" rpy="3.1416 -1.5708 0"/>
      <mass value="1.0"/>
      <inertia
        ixx="0.500990" ixy="0.0" ixz="0.0"
        iyy="0.000990" iyz="0.0"
        izz="0.000313"/>
    </inertial>
  </link>



  <!-- *** Motor 6 Output: Sphere1 *** -->

  <joint name="attach-sphere" type="fixed">
    <parent link="tip_elbow"/>
    <child  link="sphere"/>
  </joint>
  <link name="sphere">
    <visual>
      <origin xyz="0 0 0" rpy="0 0 0"/>
      <geometry>
	      <sphere radius="0.01"/>
      </geometry>
      <material name="green"/>
    </visual>
    <collision>
      <origin xyz="0 -0.05 0" rpy="0 0 0"/>
      <geometry>
	      <sphere radius="0.01"/>
      </geometry>
      <material name="green"/>
    </collision>
    <inertial>
      <origin xyz="0 0 0" rpy="0 0 0"/>
      <mass value="0.01"/>
      <inertia
        ixx="0.01" ixy="0.0" ixz="0.0"
        iyy="0.01" iyz="0.0"
        izz="0.01"/>
    </inertial>
  </link>

  <joint name="attach-cylinder" type="fixed">
    <parent link="tip_elbow"/>
    <child  link="cylinder"/>
  </joint>
  <link name="cylinder">
    <visual>
      <origin xyz="0 -0.05 0" rpy="1.5708 0 0"/>
      <geometry>
	      <cylinder length="0.1" radius="0.01"/>
      </geometry>
      <material name="gray"/>
    </visual>
    <collision>
      <origin xyz="0 -0.1 0" rpy="1.5708 0 0"/>
      <geometry>
	      <cylinder length="0.1" radius="0.01"/>
      </geometry>
    </collision>
    <inertial>
      <origin xyz="0 -0.1 0" rpy="1.5708 0 0"/>
      <mass value="0.01"/>
      <inertia
        ixx="0.500990" ixy="0.0" ixz="0.0"
        iyy="0.000990" iyz="0.0"
        izz="0.000313"/>
    </inertial>
  </link>

  <!-- *** Motor 12 Output: Sphere2 *** -->

  <joint name="attach-sphere2" type="fixed">
    <parent link="tip_full"/>
    <child  link="sphere2"/>
  </joint>
  <link name="sphere2">
    <visual>
      <origin xyz="0 0 0" rpy="0 0 0"/>
      <geometry>
	      <sphere radius="0.01"/>
      </geometry>
      <material name="green"/>
    </visual>
    <collision>
      <origin xyz="0 -0.05 0" rpy="0 0 0"/>
      <geometry>
	      <sphere radius="0.01"/>
      </geometry>
      <material name="green"/>
    </collision>
    <inertial>
      <origin xyz="0 0 0" rpy="0 0 0"/>
      <mass value="0.01"/>
      <inertia
        ixx="0.01" ixy="0.0" ixz="0.0"
        iyy="0.01" iyz="0.0"
        izz="0.01"/>
    </inertial>
  </link>

  <joint name="attach-cylinder2" type="fixed">
    <parent link="tip_full"/>
    <child  link="cylinder2"/>
  </joint>
  <link name="cylinder2">
    <visual>
      <origin xyz="0 -0.015 0" rpy="1.5708 0 0"/>
      <geometry>
	      <cylinder length="0.03" radius="0.01"/>
      </geometry>
      <material name="gray"/>
    </visual>
    <collision>
      <origin xyz="0 -0.015 0" rpy="1.5708 0 0"/>
      <geometry>
	      <cylinder length="0.03" radius="0.01"/>
      </geometry>
    </collision>
    <inertial>
      <origin xyz="0 -0.015 0" rpy="1.5708 0 0"/>
      <mass value="0.1"/>
      <inertia
        ixx="0.500990" ixy="0.0" ixz="0.0"
        iyy="0.000990" iyz="0.0"
        izz="0.000313"/>
    </inertial>
  </link>



  <!-- *************************************************** -->
  <!-- ******************* Gazebo Colors ***************** -->
  <!-- *************************************************** -->
  <gazebo reference="base_link"> <material>Gazebo/Gray</material>  </gazebo>
  <gazebo reference="link1"> <material>Gazebo/Grass</material>  </gazebo>
  <gazebo reference="link2"> <material>Gazebo/Grass</material>  </gazebo>
  <gazebo reference="link3"> <material>Gazebo/Grass</material>  </gazebo>
  <gazebo reference="link4"> <material>Gazebo/Grass</material>  </gazebo>
  <gazebo reference="link5"> <material>Gazebo/Grass</material>  </gazebo>
  <gazebo reference="link6"> <material>Gazebo/Grass</material>  </gazebo>
  <gazebo reference="link7"> <material>Gazebo/Grass</material>  </gazebo>
  <gazebo reference="link8"> <material>Gazebo/Grass</material>  </gazebo>
  <gazebo reference="link9"> <material>Gazebo/Grass</material>  </gazebo>
  <gazebo reference="link10"> <material>Gazebo/Grass</material>  </gazebo>
  <gazebo reference="link11"> <material>Gazebo/Grass</material>  </gazebo>
  <gazebo reference="link12"> <material>Gazebo/Grass</material>  </gazebo>

  <gazebo reference="motor1"> <material>Gazebo/Gray</material>  </gazebo>
  <gazebo reference="motor2"> <material>Gazebo/Gray</material>  </gazebo>
  <gazebo reference="motor3"> <material>Gazebo/Gray</material>  </gazebo>
  <gazebo reference="motor4"> <material>Gazebo/Gray</material>  </gazebo>
  <gazebo reference="motor5"> <material>Gazebo/Gray</material>  </gazebo>
  <gazebo reference="motor6"> <material>Gazebo/Gray</material>  </gazebo>
  <gazebo reference="motor7"> <material>Gazebo/Gray</material>  </gazebo>
  <gazebo reference="motor8"> <material>Gazebo/Gray</material>  </gazebo>
  <gazebo reference="motor9"> <material>Gazebo/Gray</material>  </gazebo>
  <gazebo reference="motor10"> <material>Gazebo/Gray</material>  </gazebo>
  <gazebo reference="motor11"> <material>Gazebo/Gray</material>  </gazebo>
  <gazebo reference="motor12"> <material>Gazebo/Gray</material>  </gazebo>

  <gazebo reference="mount1">   <material>Gazebo/Black</material> </gazebo>
  <gazebo reference="mount2">   <material>Gazebo/Black</material> </gazebo>
  <gazebo reference="mount3">   <material>Gazebo/Black</material> </gazebo>
  <gazebo reference="mount4">   <material>Gazebo/Black</material> </gazebo>
  <gazebo reference="mount5">   <material>Gazebo/Black</material> </gazebo>
  <gazebo reference="mount6">   <material>Gazebo/Black</material> </gazebo>
  <gazebo reference="mount7">   <material>Gazebo/Black</material> </gazebo>
  <gazebo reference="mount8">   <material>Gazebo/Black</material> </gazebo>
  <gazebo reference="mount9">   <material>Gazebo/Black</material> </gazebo>
  <gazebo reference="mount10">   <material>Gazebo/Black</material> </gazebo>
  <gazebo reference="mount11">   <material>Gazebo/Black</material> </gazebo>
  <gazebo reference="mount12">   <material>Gazebo/Black</material> </gazebo>

  <gazebo reference="sphere">  <material>Gazebo/Green</material>  </gazebo>
  <gazebo reference="sphere2">  <material>Gazebo/Green</material>  </gazebo>  
 



  <!-- *************************************************** -->
  <!-- ************** Gazebo Transmissions *************** -->
  <!-- *************************************************** -->

  <transmission name="trans1">
    <type>transmission_interface/SimpleTransmission</type>
    <joint name="theta1">
      <hardwareInterface>hardware_interface/EffortJointInterface</hardwareInterface>
    </joint>
    <actuator name="motor1">
      <mechanicalReduction>1</mechanicalReduction>
      <hardwareInterface>hardware_interface/EffortJointInterface</hardwareInterface>
    </actuator>
  </transmission>
  
  <transmission name="trans2">
    <type>transmission_interface/SimpleTransmission</type>
    <joint name="theta2">
      <hardwareInterface>hardware_interface/EffortJointInterface</hardwareInterface>
    </joint>
    <actuator name="motor2">
      <mechanicalReduction>1</mechanicalReduction>
      <hardwareInterface>hardware_interface/EffortJointInterface</hardwareInterface>
    </actuator>
  </transmission>
  
  <transmission name="trans3">
    <type>transmission_interface/SimpleTransmission</type>
    <joint name="theta3">
      <hardwareInterface>hardware_interface/EffortJointInterface</hardwareInterface>
    </joint>
    <actuator name="motor3">
      <mechanicalReduction>1</mechanicalReduction>
      <hardwareInterface>hardware_interface/EffortJointInterface</hardwareInterface>
    </actuator>
  </transmission>
  
  <transmission name="trans4">
    <type>transmission_interface/SimpleTransmission</type>
    <joint name="theta4">
      <hardwareInterface>hardware_interface/EffortJointInterface</hardwareInterface>
    </joint>
    <actuator name="motor4">
      <mechanicalReduction>1</mechanicalReduction>
      <hardwareInterface>hardware_interface/EffortJointInterface</hardwareInterface>
    </actuator>
  </transmission>
  
  <transmission name="trans5">
    <type>transmission_interface/SimpleTransmission</type>
    <joint name="theta5">
      <hardwareInterface>hardware_interface/EffortJointInterface</hardwareInterface>
    </joint>
    <actuator name="motor5">
      <mechanicalReduction>1</mechanicalReduction>
      <hardwareInterface>hardware_interface/EffortJointInterface</hardwareInterface>
    </actuator>
  </transmission>
  
  <transmission name="trans6">
    <type>transmission_interface/SimpleTransmission</type>
    <joint name="theta6">
      <hardwareInterface>hardware_interface/EffortJointInterface</hardwareInterface>
    </joint>
    <actuator name="motor6">
      <mechanicalReduction>1</mechanicalReduction>
      <hardwareInterface>hardware_interface/EffortJointInterface</hardwareInterface>
    </actuator>
  </transmission>
  
  <transmission name="trans7">
    <type>transmission_interface/SimpleTransmission</type>
    <joint name="theta7">
      <hardwareInterface>hardware_interface/EffortJointInterface</hardwareInterface>
    </joint>
    <actuator name="motor7">
      <mechanicalReduction>1</mechanicalReduction>
      <hardwareInterface>hardware_interface/EffortJointInterface</hardwareInterface>
    </actuator>
  </transmission>

  <transmission name="trans8">
    <type>transmission_interface/SimpleTransmission</type>
    <joint name="theta8">
      <hardwareInterface>hardware_interface/EffortJointInterface</hardwareInterface>
    </joint>
    <actuator name="motor8">
      <mechanicalReduction>1</mechanicalReduction>
      <hardwareInterface>hardware_interface/EffortJointInterface</hardwareInterface>
    </actuator>
  </transmission>

  <transmission name="trans9">
    <type>transmission_interface/SimpleTransmission</type>
    <joint name="theta9">
      <hardwareInterface>hardware_interface/EffortJointInterface</hardwareInterface>
    </joint>
    <actuator name="motor9">
      <mechanicalReduction>1</mechanicalReduction>
      <hardwareInterface>hardware_interface/EffortJointInterface</hardwareInterface>
    </actuator>
  </transmission>

  <transmission name="trans10">
    <type>transmission_interface/SimpleTransmission</type>
    <joint name="theta10">
      <hardwareInterface>hardware_interface/EffortJointInterface</hardwareInterface>
    </joint>
    <actuator name="motor10">
      <mechanicalReduction>1</mechanicalReduction>
      <hardwareInterface>hardware_interface/EffortJointInterface</hardwareInterface>
    </actuator>
  </transmission>

  <transmission name="trans11">
    <type>transmission_interface/SimpleTransmission</type>
    <joint name="theta11">
      <hardwareInterface>hardware_interface/EffortJointInterface</hardwareInterface>
    </joint>
    <actuator name="motor11">
      <mechanicalReduction>1</mechanicalReduction>
      <hardwareInterface>hardware_interface/EffortJointInterface</hardwareInterface>
    </actuator>
  </transmission>

  <transmission name="trans12">
    <type>transmission_interface/SimpleTransmission</type>
    <joint name="theta12">
      <hardwareInterface>hardware_interface/EffortJointInterface</hardwareInterface>
    </joint>
    <actuator name="motor12">
      <mechanicalReduction>1</mechanicalReduction>
      <hardwareInterface>hardware_interface/EffortJointInterface</hardwareInterface>
    </actuator>
  </transmission>

  
  <!-- *************************************************** -->
  <!-- *************** Gazebo Controllers **************** -->
  <!-- *************************************************** -->

  <gazebo>
    <plugin name="gazebo_ros_control" filename="libgazebo_ros_control.so">
      <robotNamespace>/twelvedof</robotNamespace>
      <robotSimType>gazebo_ros_control/DefaultRobotHWSim</robotSimType>
    </plugin>
  </gazebo>



</robot>
