<?xml version="1.0" encoding="utf-8"?>
<!-- This URDF was automatically created by SolidWorks to URDF Exporter! Originally created by Stephen Brawner (brawner@gmail.com) 
     Commit Version: 1.6.0-1-g15f4949  Build Version: 1.6.7594.29634
     For more information, please see http://wiki.ros.org/sw_urdf_exporter -->
<robot
  name="twelvedof">
  
  <link name="world"/>
    
  <joint name="worldjoint" type="fixed">
    <origin xyz="0 0 0" rpy="0 0 0" />
    <parent link="world" />
    <child link="base_link" />
  </joint>

  <link name="base_link">
    <inertial>
      <origin
        xyz="-7.9441E-34 1.4856E-18 0.035234"
        rpy="0 0 0" />
      <mass
        value="10" />
      <inertia
        ixx="0.002379"
        ixy="3.1576E-35"
        ixz="-1.5303E-35"
        iyy="0.002379"
        iyz="-3.5773E-19"
        izz="0.0025484" />
    </inertial>
    <visual>
      <origin xyz="0 0 0" rpy="0 0 0" />
      <geometry>
        <mesh filename="package://twelvedof/meshes/base_link.STL" />
      </geometry>
      <material name="">
        <color rgba="0.89804 0.91765 0.92941 1" />
      </material>
    </visual>
  </link>
    
  <joint name="theta1" type="continuous">
    <origin xyz="0 0 0.105" rpy="1.5708 0 0" />
    <parent link="base_link" />
    <child link="link1" />
    <axis xyz="0 1 0" />
    <dynamics damping="1.0"/>
  </joint>

  <link name="link1">
    <inertial>
      <origin
        xyz="-1.419E-18 0.069921 -7.0908E-19"
        rpy="0 0 0" />
      <mass
        value="0.12918" />
      <inertia
        ixx="0.00038933"
        ixy="1.554E-20"
        ixz="-3.5807E-10"
        iyy="5.0815E-05"
        iyz="-1.9525E-20"
        izz="0.000405" />
    </inertial>
    <visual>
      <origin xyz="0 0 0" rpy="0 0 0" />
      <geometry>
        <mesh filename="package://twelvedof/meshes/link1.STL" />
      </geometry>
      <material name="">
        <color rgba="0.89804 0.91765 0.92941 1" />
      </material>
    </visual>
  </link>

  <joint name="theta2" type="continuous">
    <origin xyz="0 0.17 0" rpy="1.5708 1.5708 0" />
    <parent link="link1" />
    <child link="link2" />
    <axis xyz="0 1 0" />
    <dynamics damping="1.0"/>
  </joint>
  
  <link name="link2">
    <inertial>
      <origin
        xyz="0.07 -7.4661E-18 -2.6756E-09"
        rpy="0 0 0" />
      <mass
        value="0.13136" />
      <inertia
        ixx="1.9122E-05"
        ixy="4.4167E-20"
        ixz="-4.1467E-11"
        iyy="0.00034685"
        iyz="-2.4668E-11"
        izz="0.00035017" />
    </inertial>
    <visual>
      <origin xyz="0 0 0" rpy="0 0 0" />
      <geometry>
        <mesh filename="package://twelvedof/meshes/link2.STL" />
      </geometry>
      <material name="">
        <color rgba="0.79216 0.81961 0.93333 1" />
      </material>
    </visual>
  </link>
  
  <joint name="theta3" type="continuous">
    <origin xyz="0.14 0 0" rpy="0 0 1.5707963267949" />
    <parent link="link2" />
    <child link="link3" />
    <axis xyz="1 0 0" />
    <dynamics damping="1.0"/>
  </joint>
  
  <link name="link3">
    <inertial>
      <origin
        xyz="1.39165419042562E-10 -0.055569036831021 1.50739365434305E-10"
        rpy="0 0 0" />
      <mass
        value="0.0532676480842889" />
      <inertia
        ixx="7.17068684111301E-05"
        ixy="-2.2073271379026E-14"
        ixz="-1.1411130364755E-10"
        iyy="1.66776723198201E-05"
        iyz="-3.9646299805838E-14"
        izz="8.52612221768292E-05" />
    </inertial>
    <visual>
      <origin xyz="0 0 0" rpy="0 0 0" />
      <geometry>
        <mesh filename="package://twelvedof/meshes/link3.STL" />
      </geometry>
      <material name="">
        <color rgba="0.792156862745098 0.819607843137255 0.933333333333333 1" />
      </material>
    </visual>
  </link>
 
  <joint name="theta4" type="continuous">
    <origin xyz="0 -0.13 0" rpy="0 0 3.14159265358979" />
    <parent link="link3" />
    <child link="link4" />
    <axis xyz="0 1 0" />
    <dynamics damping="1.0"/>
  </joint>
 
  <link name="link4">
    <inertial>
      <origin
        xyz="3.66680228788307E-10 0.0744309630757226 4.57771598405543E-11"
        rpy="0 0 0" />
      <mass
        value="0.0532676474780037" />
      <inertia
        ixx="7.17068683212608E-05"
        ixy="-1.36945613265618E-13"
        ixz="-1.14230929893076E-10"
        iyy="1.66776720100514E-05"
        iyz="1.00418867716223E-14"
        izz="8.52612218841434E-05" />
    </inertial>
    <visual>
      <origin xyz="0 0 0" rpy="0 0 0" />
      <geometry>
        <mesh filename="package://twelvedof/meshes/link4.STL" />
      </geometry>
      <material name="">
        <color rgba="0.792156862745098 0.819607843137255 0.933333333333333 1" />
      </material>
    </visual>
  </link>

  <joint name="theta5" type="continuous">
    <origin xyz="0 0.13 0" rpy="0 -1.5707963267949 0" />
    <parent link="link4" />
    <child link="link5" />
    <axis xyz="0 0 1" />
    <dynamics damping="1.0"/>
  </joint>

  <link name="link5">
    <inertial>
      <origin
        xyz="-1.32641759797991E-08 1.7454444556364E-09 1.81333805274857E-07"
        rpy="0 0 0" />
      <mass
        value="0.00994148578496848" />
      <inertia
        ixx="1.54538351353866E-06"
        ixy="1.86661466040859E-12"
        ixz="-5.08179849707645E-12"
        iyy="1.51571936007817E-06"
        iyz="-3.23276961224318E-12"
        izz="6.20263989581308E-07" />
    </inertial>
    <visual>
      <origin xyz="0 0 0" rpy="0 0 0" />
      <geometry>
        <mesh filename="package://twelvedof/meshes/link5.STL" />
      </geometry>
      <material name="">
        <color rgba="0.898039215686275 0.917647058823529 0.929411764705882 1" />
      </material>
    </visual>
  </link>

  <joint name="theta6" type="continuous">
    <origin xyz="0 0 0" rpy="-3.14159265358979 0 0" />
    <parent link="link5" />
    <child link="link6" />
    <axis xyz="1 0 0" />
    <dynamics damping="1.0"/>
  </joint>

  <link name="link6">
    <inertial>
      <origin
        xyz="-8.98395696724563E-09 -0.0600000346635212 0.00167698865762602"
        rpy="0 0 0" />
      <mass
        value="0.0570027293868964" />
      <inertia
        ixx="8.72110819353783E-05"
        ixy="2.83939957777628E-10"
        ixz="5.72306396551074E-12"
        iyy="1.66281845808555E-05"
        iyz="2.87090876599928E-11"
        izz="8.79631628732104E-05" />
    </inertial>
    <visual>
      <origin xyz="0 0 0" rpy="0 0 0" />
      <geometry>
        <mesh filename="package://twelvedof/meshes/link6.STL" />
      </geometry>
      <material name="">
        <color rgba="0.792156862745098 0.819607843137255 0.933333333333333 1" />
      </material>
    </visual>
  </link>

  <joint name="final1" type="fixed">
    <parent link="link6"/>
    <child  link="tip_elbow"/>
    <origin xyz="0.1 0.0 0.2" rpy="1.5708 1.5708 0"/>
  </joint>

  <link name="tip_elbow"/>
  
  
<!-- SECOND HALF OF ARM -->


  <joint name="theta7" type="continuous">
    <origin xyz="0 -0.12 0" rpy="0 0 3.14159265358979" />
    <parent link="link6" />
    <child link="link7" />
    <axis xyz="1 0 0" />
    <dynamics damping="0.8"/>
  </joint>

  <link name="link7">
    <inertial>
      <origin
        xyz="-1.32641757577545E-08 1.7454445666587E-09 1.81333805254885E-07"
        rpy="0 0 0" />
      <mass
        value="0.00994148578496851" />
      <inertia
        ixx="1.54538351353867E-06"
        ixy="1.86661466222653E-12"
        ixz="-5.08179849667178E-12"
        iyy="1.51571936007817E-06"
        iyz="-3.2327696128287E-12"
        izz="6.20263989581311E-07" />
    </inertial>
    <visual>
      <origin xyz="0 0 0" rpy="0 0 0" />
      <geometry>
        <mesh filename="package://twelvedof/meshes/link7.STL" />
      </geometry>
      <material name="">
        <color rgba="0.898039215686275 0.917647058823529 0.929411764705882 1" />
      </material>
    </visual>
  </link>

  <joint name="theta8" type="continuous">
    <origin xyz="0 0 0" rpy="3.14159265358979 1.5707963267949 0" />
    <parent link="link7" />
    <child link="link8" />
    <axis xyz="1 0 0" />
    <dynamics damping="0.8"/>
  </joint>

  <link name="link8">
    <inertial>
      <origin
        xyz="-8.83495037608582E-11 -0.0555690369242776 2.55700793871938E-10"
        rpy="0 0 0" />
      <mass
        value="0.0532676474780038" />
      <inertia
        ixx="7.17068683212609E-05"
        ixy="9.27992182478001E-14"
        ixz="-1.14230930028211E-10"
        iyy="1.66776720100514E-05"
        iyz="-8.93351379369638E-14"
        izz="8.52612218841436E-05" />
    </inertial>
    <visual>
      <origin xyz="0 0 0" rpy="0 0 0" />
      <geometry>
        <mesh filename="package://twelvedof/meshes/link8.STL" />
      </geometry>
      <material name="">
        <color rgba="0.792156862745098 0.819607843137255 0.933333333333333 1" />
      </material>
    </visual>
  </link>

  <joint name="theta9" type="continuous">
    <origin xyz="0 -0.13 0" rpy="-3.14159265358978 0 0" />
    <parent link="link8" />
    <child link="link9" />
    <axis xyz="0 1 0" />
    <dynamics damping="0.8"/>
  </joint>

  <link name="link9">
    <inertial>
      <origin
        xyz="-8.83494916528465E-11 0.0744309630757227 2.55701515516904E-10"
        rpy="0 0 0" />
      <mass
        value="0.0532676474780037" />
      <inertia
        ixx="7.17068683212611E-05"
        ixy="9.27991842210463E-14"
        ixz="-1.14230929898427E-10"
        iyy="1.66776720100515E-05"
        iyz="-8.93344383273059E-14"
        izz="8.52612218841439E-05" />
    </inertial>
    <visual>
      <origin xyz="0 0 0" rpy="0 0 0" />
      <geometry>
        <mesh filename="package://twelvedof/meshes/link9.STL" />
      </geometry>
      <material name="">
        <color rgba="0.792156862745098 0.819607843137255 0.933333333333333 1" />
      </material>
    </visual>
  </link>
 
  <joint name="theta10" type="continuous">
    <origin xyz="0 0.13 0" rpy="3.14159265358979 0 1.5707963267949" />
    <parent link="link9" />
    <child link="link10" />
    <axis xyz="0 1 0" />
    <dynamics damping="0.8"/>
  </joint>
 
  <link name="link10">
    <inertial>
      <origin
        xyz="0.0858647819115578 -4.94694969462831E-05 4.79974323619459E-08"
        rpy="0 0 0" />
      <mass
        value="0.0743981881209823" />
      <inertia
        ixx="1.87713917621073E-05"
        ixy="-3.1603968463363E-07"
        ixz="2.00084585094285E-10"
        iyy="0.000245163362524828"
        iyz="3.88373017940527E-11"
        izz="0.000232598980003436" />
    </inertial>
    <visual>
      <origin xyz="0 0 0" rpy="0 0 0" />
      <geometry>
        <mesh filename="package://twelvedof/meshes/link10.STL" />
      </geometry>
      <material name="">
        <color rgba="0.792156862745098 0.819607843137255 0.933333333333333 1" />
      </material>
    </visual>
  </link>
 
  <joint name="theta11" type="continuous">
    <origin xyz="0.17 0 0" rpy="3.14159265358979 0 0" />
    <parent link="link10" />
    <child link="link11" />
    <axis xyz="0 0 1" />
    <dynamics damping="0.5"/>
  </joint>
 

  <link name="link11">
    <inertial>
      <origin
        xyz="-1.32641758687768E-08 1.74544477010197E-09 1.81333805249206E-07"
        rpy="0 0 0" />
      <mass
        value="0.0099414857849685" />
      <inertia
        ixx="1.54538351353871E-06"
        ixy="1.86623347652368E-12"
        ixz="-5.08179853781339E-12"
        iyy="1.51571936007812E-06"
        iyz="-3.23276954505056E-12"
        izz="6.20263989581311E-07" />
    </inertial>
    <visual>
      <origin xyz="0 0 0" rpy="0 0 0" />
      <geometry>
        <mesh filename="package://twelvedof/meshes/link11.STL" />
      </geometry>
      <material name="">
        <color rgba="0.898039215686275 0.917647058823529 0.929411764705882 1" />
      </material>
    </visual>
  </link>

  <joint name="theta12" type="continuous">
    <origin xyz="0 0 0" rpy="1.5707963267949 0 0" />
    <parent link="link11" />
    <child link="link12" />
    <axis xyz="1 0 0" />
    <dynamics damping="0.3"/>
  </joint>

  <link name="link12">
    <inertial>
      <origin
        xyz="3.18930326592692E-10 0 -0.0248194012953823"
        rpy="0 0 0" />
      <mass
        value="0.0230261093724122" />
      <inertia
        ixx="1.31880218422786E-05"
        ixy="-8.33050257778651E-12"
        ixz="1.06952381355644E-13"
        iyy="1.66498223037003E-05"
        iyz="-9.93988576856652E-20"
        izz="4.86490776895599E-06" />
    </inertial>
    <visual>
      <origin xyz="0 0 0" rpy="0 0 0" />
      <geometry>
        <mesh filename="package://twelvedof/meshes/link12.STL" />
      </geometry>
      <material name="">
        <color rgba="0.898039215686275 0.917647058823529 0.929411764705882 1" />
      </material>
    </visual>
  </link>

  <joint name="final2" type="fixed">
    <parent link="link12"/>
    <child  link="tip_full"/>
    <origin xyz="0 0 0.125" rpy="1.5708 1.5708 0"/>
  </joint>

  <link name="tip_full"/>










  <!-- *************************************************** -->
  <!-- ****** Building Blocks (Visual AND Inertial) ****** -->
  <!-- *************************************************** -->

  <!-- *** base_link-Fixed: Mount 1, Motor 1 *** -->

  <joint name="attach-mount1" type="fixed">
    <parent link="base_link"/>
    <child  link="mount1"/>
  </joint>
  <link name="mount1">
    <visual>
      <origin xyz="0 0 0.105" rpy="0 0 0"/>
      <geometry>
  <cylinder length="0.05" radius="0.011"/>
      </geometry>
      <material name="black"/>
    </visual>
    <collision>
      <origin xyz="0 0 0.105" rpy="0 0 0"/>
      <geometry>
  <cylinder length="0.05" radius="0.011"/>
      </geometry>
    </collision>
    <inertial>
      <origin xyz="0 0 0.105" rpy="0 0 0"/>
      <mass value="0.2"/>
      <inertia
        ixx="0.000687" ixy="0.0" ixz="0.0"
        iyy="0.000687" iyz="0.0"
        izz="1.000040"/>
    </inertial>
  </link>

  <joint name="attach-motor1" type="fixed">
    <parent link="base_link"/>
    <child  link="motor1"/>
  </joint>
  <link name="motor1">
    <visual>
      <origin xyz="0 0 0.105" rpy="0 0 0"/>
      <geometry>
  <cylinder length="0.1" radius="0.02"/>
      </geometry>
      <material name="gray"/>
    </visual>
    <collision>
      <origin xyz="0 0 0.105" rpy="0 0 0"/>
      <geometry>
  <cylinder length="0.1" radius="0.02"/>
      </geometry>
    </collision>
    <inertial>
      <origin xyz="0 0 0.405" rpy="0 0 0"/>
      <mass value="2.0"/>
      <inertia
        ixx="0.500990" ixy="0.0" ixz="0.0"
        iyy="0.000990" iyz="0.0"
        izz="0.000313"/>
    </inertial>
  </link>


  <!-- *** Motor 1 Output: Mount 2, Motor 2 *** -->

  <joint name="attach-mount2" type="fixed">
    <parent link="link1"/>
    <child  link="mount2"/>
  </joint>
  <link name="mount2">
    <visual>
      <origin xyz="0 0.17 0" rpy="0 -1.5708 0"/>
      <geometry>
  <cylinder length="0.05" radius="0.005"/>
      </geometry>
      <material name="black"/>
    </visual>
    <collision>
      <origin xyz="0 0.17 0" rpy="0 -1.5708 0"/>
      <geometry>
  <cylinder length="0.05" radius="0.005"/>
      </geometry>
    </collision>
    <inertial>
      <origin xyz="0 0.17 0" rpy="0 -1.5708 0"/>
      <mass value="0.2"/>
      <inertia
        ixx="0.000687" ixy="0.0" ixz="0.0"
        iyy="0.000687" iyz="0.0"
        izz="1.000040"/>
    </inertial>
  </link>

  <joint name="attach-motor2" type="fixed">
    <parent link="link1"/>
    <child  link="motor2"/>
  </joint>
  <link name="motor2">
    <visual>
      <origin xyz="0 0.17 0" rpy="0 -1.5708 0"/>
      <geometry>
  <cylinder length="0.1" radius="0.011"/>
      </geometry>
      <material name="gray"/>
    </visual>
    <collision>
      <origin xyz="0 0.17 0" rpy="0 -1.5708 0"/>
      <geometry>
  <cylinder length="0.1" radius="0.011"/>
      </geometry>
    </collision>
    <inertial>
      <origin xyz="0 0.17 0" rpy="0 -1.5708 0"/>
      <mass value="2.0"/>
      <inertia
        ixx="0.500990" ixy="0.0" ixz="0.0"
        iyy="0.000990" iyz="0.0"
        izz="0.000313"/>
    </inertial>
  </link>


  <!-- *** Motor 2 Output: Mount 3, Motor 3 *** -->

  <joint name="attach-mount3" type="fixed">
    <parent link="link2"/>
    <child  link="mount3"/>
  </joint>
  <link name="mount3">
    <visual>
      <origin xyz="0.14 0 0" rpy="0 -1.5708 -1.5708"/>
      <geometry>
  <cylinder length="0.05" radius="0.005"/>
      </geometry>
      <material name="black"/>
    </visual>
    <collision>
      <origin xyz="0.14 0 0" rpy="0 -1.5708 -1.5708"/>
      <geometry>
  <cylinder length="0.05" radius="0.005"/>
      </geometry>
    </collision>
    <inertial>
      <origin xyz="0.14 0 0" rpy="0 -1.5708 -1.5708"/>
      <mass value="0.2"/>
      <inertia
        ixx="0.000687" ixy="0.0" ixz="0.0"
        iyy="0.000687" iyz="0.0"
        izz="1.000040"/>
    </inertial>
  </link>

  <joint name="attach-motor3" type="fixed">
    <parent link="link2"/>
    <child  link="motor3"/>
  </joint>
  <link name="motor3">
    <visual>
      <origin xyz="0.14 0 0" rpy="0 -1.5708 -1.5708"/>
      <geometry>
  <cylinder length="0.1" radius="0.011"/>
      </geometry>
      <material name="gray"/>
    </visual>
    <collision>
      <origin xyz="0.14 0 0" rpy="0 -1.5708 -1.5708"/>
      <geometry>
  <cylinder length="0.1" radius="0.011"/>
      </geometry>
    </collision>
    <inertial>
      <origin xyz="0.14 0 0" rpy="0 -1.5708 -1.5708"/>
      <mass value="2.0"/>
      <inertia
        ixx="0.500990" ixy="0.0" ixz="0.0"
        iyy="0.000990" iyz="0.0"
        izz="0.000313"/>
    </inertial>
  </link>


  <!-- *** Motor 3 Output: Mount 4, Motor 4 *** -->

  <joint name="attach-mount4" type="fixed">
    <parent link="link3"/>
    <child  link="mount4"/>
  </joint>
  <link name="mount4">
    <visual>
      <origin xyz="0 -0.13 0" rpy="-1.5708 0 0"/>
      <geometry>
  <cylinder length="0.035" radius="0.011"/>
      </geometry>
      <material name="black"/>
    </visual>
    <collision>
      <origin xyz="0 -0.13 0" rpy="-1.5708 0 0"/>
      <geometry>
  <cylinder length="0.035" radius="0.011"/>
      </geometry>
    </collision>
    <inertial>
      <origin xyz="0 -0.13 0" rpy="-1.5708 0 0"/>
      <mass value="0.2"/>
      <inertia
        ixx="0.000687" ixy="0.0" ixz="0.0"
        iyy="0.000687" iyz="0.0"
        izz="1.000040"/>
    </inertial>
  </link>

  <joint name="attach-motor4" type="fixed">
    <parent link="link3"/>
    <child  link="motor4"/>
  </joint>
  <link name="motor4">
    <visual>
      <origin xyz="0 -0.13 0" rpy="-1.5708 0 0"/>
      <geometry>
  <cylinder length="0.07" radius="0.02"/>
      </geometry>
      <material name="gray"/>
    </visual>
    <collision>
      <origin xyz="0 -0.13 0" rpy="-1.5708 0 0"/>
      <geometry>
  <cylinder length="0.07" radius="0.02"/>
      </geometry>
    </collision>
    <inertial>
      <origin xyz="0 -0.13 0" rpy="-1.5708 0 0"/>
      <mass value="1.5"/>
      <inertia
        ixx="0.500990" ixy="0.0" ixz="0.0"
        iyy="0.000990" iyz="0.0"
        izz="0.000313"/>
    </inertial>
  </link>


  <!-- *** Motor 4 Output: Mount 5, Motor 5 *** -->

  <joint name="attach-mount5" type="fixed">
    <parent link="link4"/>
    <child  link="mount5"/>
  </joint>
  <link name="mount5">
    <visual>
      <origin xyz="0 0.13 0" rpy="0 -1.5708 0"/>
      <geometry>
  <cylinder length="0.05" radius="0.005"/>
      </geometry>
      <material name="black"/>
    </visual>
    <collision>
      <origin xyz="0 0.13 0" rpy="0 -1.5708 0"/>
      <geometry>
  <cylinder length="0.05" radius="0.005"/>
      </geometry>
    </collision>
    <inertial>
      <origin xyz="0 0.13 0" rpy="0 -1.5708 0"/>
      <mass value="0.2"/>
      <inertia
        ixx="0.000687" ixy="0.0" ixz="0.0"
        iyy="0.000687" iyz="0.0"
        izz="1.000040"/>
    </inertial>
  </link>

  <joint name="attach-motor5" type="fixed">
    <parent link="link4"/>
    <child  link="motor5"/>
  </joint>
  <link name="motor5">
    <visual>
      <origin xyz="0 0.13 0" rpy="0 -1.5708 0"/>
      <geometry>
  <cylinder length="0.1" radius="0.011"/>
      </geometry>
      <material name="gray"/>
    </visual>
    <collision>
      <origin xyz="0 0.13 0" rpy="0 -1.5708 0"/>
      <geometry>
  <cylinder length="0.1" radius="0.011"/>
      </geometry>
    </collision>
    <inertial>
      <origin xyz="0 0.13 0" rpy="0 -1.5708 0"/>
      <mass value="1.5"/>
      <inertia
        ixx="0.500990" ixy="0.0" ixz="0.0"
        iyy="0.000990" iyz="0.0"
        izz="0.000313"/>
    </inertial>
  </link>


  <!-- *** Motor 5 Output: Mount 6, Motor 6 *** -->

  <joint name="attach-mount6" type="fixed">
    <parent link="link5"/>
    <child  link="mount6"/>
  </joint>
  <link name="mount6">
    <visual>
      <origin xyz="0 0 0" rpy="0 -1.5708 0"/>
      <geometry>
  <cylinder length="0.05" radius="0.005"/>
      </geometry>
      <material name="black"/>
    </visual>
    <collision>
      <origin xyz="0 0 0" rpy="0 -1.5708 0"/>
      <geometry>
  <cylinder length="0.05" radius="0.005"/>
      </geometry>
    </collision>
    <inertial>
      <origin xyz="0 0 0" rpy="0 -1.5708 0"/>
      <mass value="0.2"/>
      <inertia
        ixx="0.000687" ixy="0.0" ixz="0.0"
        iyy="0.000687" iyz="0.0"
        izz="1.000040"/>
    </inertial>
  </link>

  <joint name="attach-motor6" type="fixed">
    <parent link="link5"/>
    <child  link="motor6"/>
  </joint>
  <link name="motor6">
    <visual>
      <origin xyz="0 0 0" rpy="0 -1.5708 0"/>
      <geometry>
  <cylinder length="0.1" radius="0.011"/>
      </geometry>
      <material name="gray"/>
    </visual>
    <collision>
      <origin xyz="0 0 0" rpy="0 -1.5708 0"/>
      <geometry>
  <cylinder length="0.1" radius="0.011"/>
      </geometry>
    </collision>
    <inertial>
      <origin xyz="0 0 0" rpy="0 -1.5708 0"/>
      <mass value="1.5"/>
      <inertia
        ixx="0.500990" ixy="0.0" ixz="0.0"
        iyy="0.000990" iyz="0.0"
        izz="0.000313"/>
    </inertial>
  </link>


  <!-- *** Motor 6 Output: Mount 7, Motor 7 *** -->

  <joint name="attach-mount7" type="fixed">
    <parent link="link6"/>
    <child  link="mount7"/>
  </joint>
  <link name="mount7">
    <visual>
      <origin xyz="0 -0.12 0" rpy="0 0 0"/>
      <geometry>
  <cylinder length="0.05" radius="0.005"/>
      </geometry>
      <material name="black"/>
    </visual>
    <collision>
      <origin xyz="0 -0.12 0" rpy="0 0 0"/>
      <geometry>
  <cylinder length="0.05" radius="0.005"/>
      </geometry>
    </collision>
    <inertial>
      <origin xyz="0 -0.12 0" rpy="0 0 0"/>
      <mass value="0.2"/>
      <inertia
        ixx="0.000687" ixy="0.0" ixz="0.0"
        iyy="0.000687" iyz="0.0"
        izz="1.000040"/>
    </inertial>
  </link>

  <joint name="attach-motor7" type="fixed">
    <parent link="link6"/>
    <child  link="motor7"/>
  </joint>
  <link name="motor7">
    <visual>
      <origin xyz="0 -0.12 0" rpy="0 0 0"/>
      <geometry>
  <cylinder length="0.2" radius="0.011"/>
      </geometry>
      <material name="gray"/>
    </visual>
    <collision>
      <origin xyz="0 -0.12 0" rpy="0 0 0"/>
      <geometry>
  <cylinder length="0.1" radius="0.011"/>
      </geometry>
    </collision>
    <inertial>
      <origin xyz="0 -0.12 0" rpy="0 0 0"/>
      <mass value="1.5"/>
      <inertia
        ixx="0.500990" ixy="0.0" ixz="0.0"
        iyy="0.000990" iyz="0.0"
        izz="0.000313"/>
    </inertial>
  </link>


  <!-- *** Motor 7 Output: Mount 8, Motor 8 *** -->

  <joint name="attach-mount8" type="fixed">
    <parent link="link7"/>
    <child  link="mount8"/>
  </joint>
  <link name="mount8">
    <visual>
      <origin xyz="0 0 0" rpy="0 -1.5707963267949 0"/>
      <geometry>
  <cylinder length="0.05" radius="0.005"/>
      </geometry>
      <material name="black"/>
    </visual>
    <collision>
      <origin xyz="0 0 0" rpy="0 -1.5707963267949 0"/>
      <geometry>
  <cylinder length="0.05" radius="0.005"/>
      </geometry>
    </collision>
    <inertial>
      <origin xyz="0 0 0" rpy="0 -1.5707963267949 0"/>
      <mass value="0.2"/>
      <inertia
        ixx="0.000687" ixy="0.0" ixz="0.0"
        iyy="0.000687" iyz="0.0"
        izz="1.000040"/>
    </inertial>
  </link>

  <joint name="attach-motor8" type="fixed">
    <parent link="link7"/>
    <child  link="motor8"/>
  </joint>
  <link name="motor8">
    <visual>
      <origin xyz="0 0 0" rpy="0 -1.5707963267949 0"/>
      <geometry>
  <cylinder length="0.1" radius="0.011"/>
      </geometry>
      <material name="gray"/>
    </visual>
    <collision>
      <origin xyz="0 0 0" rpy="0 -1.5707963267949 0"/>
      <geometry>
  <cylinder length="0.1" radius="0.011"/>
      </geometry>
    </collision>
    <inertial>
      <origin xyz="0 0 0" rpy="0 -1.5707963267949 0"/>
      <mass value="1.0"/>
      <inertia
        ixx="0.500990" ixy="0.0" ixz="0.0"
        iyy="0.000990" iyz="0.0"
        izz="0.000313"/>
    </inertial>
  </link>


  <!-- *** Motor 8 Output: Mount 9, Motor 9 *** -->

  <joint name="attach-mount9" type="fixed">
    <parent link="link8"/>
    <child  link="mount9"/>
  </joint>
  <link name="mount9">
    <visual>
      <origin xyz="0 -0.13 0" rpy="1.5707963267949 0 0"/>
      <geometry>
  <cylinder length="0.05" radius="0.005"/>
      </geometry>
      <material name="black"/>
    </visual>
    <collision>
      <origin xyz="0 -0.13 0" rpy="1.5707963267949 0 0"/>
      <geometry>
  <cylinder length="0.05" radius="0.005"/>
      </geometry>
    </collision>
    <inertial>
      <origin xyz="0 -0.13 0" rpy="1.5707963267949 0 0"/>
      <mass value="0.2"/>
      <inertia
        ixx="0.000687" ixy="0.0" ixz="0.0"
        iyy="0.000687" iyz="0.0"
        izz="1.000040"/>
    </inertial>
  </link>

  <joint name="attach-motor9" type="fixed">
    <parent link="link8"/>
    <child  link="motor9"/>
  </joint>
  <link name="motor9">
    <visual>
      <origin xyz="0 -0.13 0" rpy="1.5707963267949 0 0"/>
      <geometry>
  <cylinder length="0.07" radius="0.02"/>
      </geometry>
      <material name="gray"/>
    </visual>
    <collision>
      <origin xyz="0 -0.13 0" rpy="1.5707963267949 0 0"/>
      <geometry>
  <cylinder length="0.07" radius="0.02"/>
      </geometry>
    </collision>
    <inertial>
      <origin xyz="0 -0.13 0" rpy="1.5707963267949 0 0"/>
      <mass value="1.0"/>
      <inertia
        ixx="0.500990" ixy="0.0" ixz="0.0"
        iyy="0.000990" iyz="0.0"
        izz="0.000313"/>
    </inertial>
  </link>


  <!-- *** Motor 9 Output: Mount 10, Motor 10 *** -->

  <joint name="attach-mount10" type="fixed">
    <parent link="link9"/>
    <child  link="mount10"/>
  </joint>
  <link name="mount10">
    <visual>
      <origin xyz="0 0.13 0" rpy="0 -1.5707963267949 0"/>
      <geometry>
  <cylinder length="0.05" radius="0.005"/>
      </geometry>
      <material name="black"/>
    </visual>
    <collision>
      <origin xyz="0 0.13 0" rpy="0 -1.5707963267949 0"/>
      <geometry>
  <cylinder length="0.05" radius="0.005"/>
      </geometry>
    </collision>
    <inertial>
      <origin xyz="0 0.13 0" rpy="0 -1.5707963267949 0"/>
      <mass value="0.2"/>
      <inertia
        ixx="0.000687" ixy="0.0" ixz="0.0"
        iyy="0.000687" iyz="0.0"
        izz="1.000040"/>
    </inertial>
  </link>

  <joint name="attach-motor10" type="fixed">
    <parent link="link9"/>
    <child  link="motor10"/>
  </joint>
  <link name="motor10">
    <visual>
      <origin xyz="0 0.13 0" rpy="0 -1.5707963267949 0"/>
      <geometry>
  <cylinder length="0.1" radius="0.011"/>
      </geometry>
      <material name="gray"/>
    </visual>
    <collision>
      <origin xyz="0 0.13 0" rpy="0 -1.5707963267949 0"/>
      <geometry>
  <cylinder length="0.1" radius="0.011"/>
      </geometry>
    </collision>
    <inertial>
      <origin xyz="0 0.13 0" rpy="0 -1.5707963267949 0"/>
      <mass value="1.0"/>
      <inertia
        ixx="0.500990" ixy="0.0" ixz="0.0"
        iyy="0.000990" iyz="0.0"
        izz="0.000313"/>
    </inertial>
  </link>


  <!-- *** Motor 10 Output: Mount 11, Motor 11 *** -->

  <joint name="attach-mount11" type="fixed">
    <parent link="link10"/>
    <child  link="mount11"/>
  </joint>
  <link name="mount11">
    <visual>
      <origin xyz="0.17 0 0" rpy="-3.14159265358979 0 0"/>
      <geometry>
  <cylinder length="0.05" radius="0.005"/>
      </geometry>
      <material name="black"/>
    </visual>
    <collision>
      <origin xyz="0.17 0 0" rpy="-3.14159265358979 0 0"/>
      <geometry>
  <cylinder length="0.05" radius="0.005"/>
      </geometry>
    </collision>
    <inertial>
      <origin xyz="0.17 0 0" rpy="-3.14159265358979 0 0"/>
      <mass value="0.2"/>
      <inertia
        ixx="0.000687" ixy="0.0" ixz="0.0"
        iyy="0.000687" iyz="0.0"
        izz="1.000040"/>
    </inertial>
  </link>

  <joint name="attach-motor11" type="fixed">
    <parent link="link10"/>
    <child  link="motor11"/>
  </joint>
  <link name="motor11">
    <visual>
      <origin xyz="0.17 0 0" rpy="-3.14159265358979 0 0"/>
      <geometry>
  <cylinder length="0.1" radius="0.011"/>
      </geometry>
      <material name="gray"/>
    </visual>
    <collision>
      <origin xyz="0.17 0 0" rpy="-3.14159265358979 0 0"/>
      <geometry>
  <cylinder length="0.1" radius="0.011"/>
      </geometry>
    </collision>
    <inertial>
      <origin xyz="0.17 0 0" rpy="-3.14159265358979 0 0"/>
      <mass value="1.0"/>
      <inertia
        ixx="0.500990" ixy="0.0" ixz="0.0"
        iyy="0.000990" iyz="0.0"
        izz="0.000313"/>
    </inertial>
  </link>


  <!-- *** Motor 11 Output: Mount 12, Motor 12 *** -->

  <joint name="attach-mount12" type="fixed">
    <parent link="link11"/>
    <child  link="mount12"/>
  </joint>
  <link name="mount12">
    <visual>
      <origin xyz="0 0 0" rpy="0 -1.5707963267949 0"/>
      <geometry>
  <cylinder length="0.05" radius="0.005"/>
      </geometry>
      <material name="black"/>
    </visual>
    <collision>
      <origin xyz="0 0 0" rpy="0 -1.5707963267949 0"/>
      <geometry>
  <cylinder length="0.05" radius="0.005"/>
      </geometry>
    </collision>
    <inertial>
      <origin xyz="0 0 0" rpy="0 -1.5707963267949 0"/>
      <mass value="0.2"/>
      <inertia
        ixx="0.000687" ixy="0.0" ixz="0.0"
        iyy="0.000687" iyz="0.0"
        izz="1.000040"/>
    </inertial>
  </link>

  <joint name="attach-motor12" type="fixed">
    <parent link="link11"/>
    <child  link="motor12"/>
  </joint>
  <link name="motor12">
    <visual>
      <origin xyz="0 0 0" rpy="0 -1.5707963267949 0"/>
      <geometry>
  <cylinder length="0.05" radius="0.011"/>
      </geometry>
      <material name="gray"/>
    </visual>
    <collision>
      <origin xyz="0 0 0" rpy="0 -1.5707963267949 0"/>
      <geometry>
  <cylinder length="0.05" radius="0.011"/>
      </geometry>
    </collision>
    <inertial>
      <origin xyz="0 0 0" rpy="0 -1.5707963267949 0"/>
      <mass value="1.0"/>
      <inertia
        ixx="0.500990" ixy="0.0" ixz="0.0"
        iyy="0.000990" iyz="0.0"
        izz="0.000313"/>
    </inertial>
  </link>



  <!-- *** Motor 6 Output: Sphere1 *** -->

  <joint name="attach-sphere1" type="fixed">
    <parent link="tip_elbow"/>
    <child  link="sphere1"/>
  </joint>
  <link name="sphere1">
    <visual>
      <origin xyz="0 -0.06 0.13" rpy="0 0 0"/>
      <geometry>
	      <sphere radius="0.005"/>
      </geometry>
      <material name="green"/>
    </visual>
    <collision>
      <origin xyz="0 -0.06 0.13" rpy="0 0 0"/>
      <geometry>
	      <sphere radius="0.005"/>
      </geometry>
      <material name="green"/>
    </collision>
    <inertial>
      <origin xyz="0 -0.06 0.13" rpy="0 0 0"/>
      <mass value="0.01"/>
      <inertia
        ixx="0.01" ixy="0.0" ixz="0.0"
        iyy="0.01" iyz="0.0"
        izz="0.01"/>
    </inertial>
  </link>

  <!-- *** Motor 12 Output: Sphere2 *** -->

  <joint name="attach-sphere2" type="fixed">
    <parent link="tip_full"/>
    <child  link="sphere2"/>
  </joint>
  <link name="sphere2">
    <visual>
      <origin xyz="0 0 -0.13" rpy="0 0 0"/>
      <geometry>
	      <sphere radius="0.005"/>
      </geometry>
      <material name="green"/>
    </visual>
    <collision>
      <origin xyz="0 0 -0.13" rpy="0 0 0"/>
      <geometry>
	      <sphere radius="0.005"/>
      </geometry>
      <material name="green"/>
    </collision>
    <inertial>
      <origin xyz="0 0 -0.13" rpy="0 0 0"/>
      <mass value="0.01"/>
      <inertia
        ixx="0.01" ixy="0.0" ixz="0.0"
        iyy="0.01" iyz="0.0"
        izz="0.01"/>
    </inertial>
  </link>




  <!-- *************************************************** -->
  <!-- ******************* Gazebo Colors ***************** -->
  <!-- *************************************************** -->

  <gazebo reference="motor1"> <material>Gazebo/Gray</material>  </gazebo>
  <gazebo reference="motor2"> <material>Gazebo/Gray</material>  </gazebo>
  <gazebo reference="motor3"> <material>Gazebo/Gray</material>  </gazebo>
  <gazebo reference="motor4"> <material>Gazebo/Gray</material>  </gazebo>
  <gazebo reference="motor5"> <material>Gazebo/Gray</material>  </gazebo>
  <gazebo reference="motor6"> <material>Gazebo/Gray</material>  </gazebo>
  <gazebo reference="motor7"> <material>Gazebo/Gray</material>  </gazebo>
  <gazebo reference="motor8"> <material>Gazebo/Gray</material>  </gazebo>
  <gazebo reference="motor9"> <material>Gazebo/Gray</material>  </gazebo>
  <gazebo reference="motor10"> <material>Gazebo/Gray</material>  </gazebo>
  <gazebo reference="motor11"> <material>Gazebo/Gray</material>  </gazebo>
  <gazebo reference="motor12"> <material>Gazebo/Gray</material>  </gazebo>

  <gazebo reference="mount1">   <material>Gazebo/Black</material> </gazebo>
  <gazebo reference="mount2">   <material>Gazebo/Black</material> </gazebo>
  <gazebo reference="mount3">   <material>Gazebo/Black</material> </gazebo>
  <gazebo reference="mount4">   <material>Gazebo/Black</material> </gazebo>
  <gazebo reference="mount5">   <material>Gazebo/Black</material> </gazebo>
  <gazebo reference="mount6">   <material>Gazebo/Black</material> </gazebo>
  <gazebo reference="mount7">   <material>Gazebo/Black</material> </gazebo>
  <gazebo reference="mount8">   <material>Gazebo/Black</material> </gazebo>
  <gazebo reference="mount9">   <material>Gazebo/Black</material> </gazebo>
  <gazebo reference="mount10">   <material>Gazebo/Black</material> </gazebo>
  <gazebo reference="mount11">   <material>Gazebo/Black</material> </gazebo>
  <gazebo reference="mount12">   <material>Gazebo/Black</material> </gazebo>

  <gazebo reference="sphere">  <material>Gazebo/Green</material>  </gazebo>
  
 



  <!-- *************************************************** -->
  <!-- ************** Gazebo Transmissions *************** -->
  <!-- *************************************************** -->

  <transmission name="trans1">
    <type>transmission_interface/SimpleTransmission</type>
    <joint name="theta1">
      <hardwareInterface>hardware_interface/EffortJointInterface</hardwareInterface>
    </joint>
    <actuator name="motor1">
      <mechanicalReduction>1</mechanicalReduction>
      <hardwareInterface>hardware_interface/EffortJointInterface</hardwareInterface>
    </actuator>
  </transmission>
  
  <transmission name="trans2">
    <type>transmission_interface/SimpleTransmission</type>
    <joint name="theta2">
      <hardwareInterface>hardware_interface/EffortJointInterface</hardwareInterface>
    </joint>
    <actuator name="motor2">
      <mechanicalReduction>1</mechanicalReduction>
      <hardwareInterface>hardware_interface/EffortJointInterface</hardwareInterface>
    </actuator>
  </transmission>
  
  <transmission name="trans3">
    <type>transmission_interface/SimpleTransmission</type>
    <joint name="theta3">
      <hardwareInterface>hardware_interface/EffortJointInterface</hardwareInterface>
    </joint>
    <actuator name="motor3">
      <mechanicalReduction>1</mechanicalReduction>
      <hardwareInterface>hardware_interface/EffortJointInterface</hardwareInterface>
    </actuator>
  </transmission>
  
  <transmission name="trans4">
    <type>transmission_interface/SimpleTransmission</type>
    <joint name="theta4">
      <hardwareInterface>hardware_interface/EffortJointInterface</hardwareInterface>
    </joint>
    <actuator name="motor4">
      <mechanicalReduction>1</mechanicalReduction>
      <hardwareInterface>hardware_interface/EffortJointInterface</hardwareInterface>
    </actuator>
  </transmission>
  
  <transmission name="trans5">
    <type>transmission_interface/SimpleTransmission</type>
    <joint name="theta5">
      <hardwareInterface>hardware_interface/EffortJointInterface</hardwareInterface>
    </joint>
    <actuator name="motor5">
      <mechanicalReduction>1</mechanicalReduction>
      <hardwareInterface>hardware_interface/EffortJointInterface</hardwareInterface>
    </actuator>
  </transmission>
  
  <transmission name="trans6">
    <type>transmission_interface/SimpleTransmission</type>
    <joint name="theta6">
      <hardwareInterface>hardware_interface/EffortJointInterface</hardwareInterface>
    </joint>
    <actuator name="motor6">
      <mechanicalReduction>1</mechanicalReduction>
      <hardwareInterface>hardware_interface/EffortJointInterface</hardwareInterface>
    </actuator>
  </transmission>
  
  <transmission name="trans7">
    <type>transmission_interface/SimpleTransmission</type>
    <joint name="theta7">
      <hardwareInterface>hardware_interface/EffortJointInterface</hardwareInterface>
    </joint>
    <actuator name="motor7">
      <mechanicalReduction>1</mechanicalReduction>
      <hardwareInterface>hardware_interface/EffortJointInterface</hardwareInterface>
    </actuator>
  </transmission>

  <transmission name="trans8">
    <type>transmission_interface/SimpleTransmission</type>
    <joint name="theta8">
      <hardwareInterface>hardware_interface/EffortJointInterface</hardwareInterface>
    </joint>
    <actuator name="motor8">
      <mechanicalReduction>1</mechanicalReduction>
      <hardwareInterface>hardware_interface/EffortJointInterface</hardwareInterface>
    </actuator>
  </transmission>

  <transmission name="trans9">
    <type>transmission_interface/SimpleTransmission</type>
    <joint name="theta9">
      <hardwareInterface>hardware_interface/EffortJointInterface</hardwareInterface>
    </joint>
    <actuator name="motor9">
      <mechanicalReduction>1</mechanicalReduction>
      <hardwareInterface>hardware_interface/EffortJointInterface</hardwareInterface>
    </actuator>
  </transmission>

  <transmission name="trans10">
    <type>transmission_interface/SimpleTransmission</type>
    <joint name="theta10">
      <hardwareInterface>hardware_interface/EffortJointInterface</hardwareInterface>
    </joint>
    <actuator name="motor10">
      <mechanicalReduction>1</mechanicalReduction>
      <hardwareInterface>hardware_interface/EffortJointInterface</hardwareInterface>
    </actuator>
  </transmission>

  <transmission name="trans11">
    <type>transmission_interface/SimpleTransmission</type>
    <joint name="theta11">
      <hardwareInterface>hardware_interface/EffortJointInterface</hardwareInterface>
    </joint>
    <actuator name="motor11">
      <mechanicalReduction>1</mechanicalReduction>
      <hardwareInterface>hardware_interface/EffortJointInterface</hardwareInterface>
    </actuator>
  </transmission>

  <transmission name="trans12">
    <type>transmission_interface/SimpleTransmission</type>
    <joint name="theta12">
      <hardwareInterface>hardware_interface/EffortJointInterface</hardwareInterface>
    </joint>
    <actuator name="motor12">
      <mechanicalReduction>1</mechanicalReduction>
      <hardwareInterface>hardware_interface/EffortJointInterface</hardwareInterface>
    </actuator>
  </transmission>

  
  <!-- *************************************************** -->
  <!-- *************** Gazebo Controllers **************** -->
  <!-- *************************************************** -->

  <gazebo>
    <plugin name="gazebo_ros_control" filename="libgazebo_ros_control.so">
      <robotNamespace>/twelvedof</robotNamespace>
      <robotSimType>gazebo_ros_control/DefaultRobotHWSim</robotSimType>
    </plugin>
  </gazebo>



</robot>
