<?xml version="1.0"?>

<robot name="twelvedof">
  
  <!-- *************************************************** -->
  <!-- ******************** Kinematics ******************* -->
  <!-- *************************************************** -->

  <link name="world"/>

  <joint name="theta1" type="continuous">
    <parent link="world"/>
    <child  link="link1"/>
    <origin xyz="0 0 0.6" rpy="0 0 0"/>
    <axis   xyz="0 0 1"/>
    <dynamics damping="5.0"/>
  </joint>

  <link name="link1"/>

  <joint name="theta2" type="continuous">
    <parent link="link1"/>
    <child  link="link2"/>
    <origin xyz="0 0 0" rpy="0 0 0"/>
    <axis   xyz="1 0 0"/>
    <dynamics damping="5.0"/>
  </joint>

  <link name="link2"/>

  <joint name="attach-shoulder" type="fixed">
    <parent link="link2"/>
    <child  link="shoulder"/>
  </joint>

  <link name="shoulder"/>

  <joint name="theta3" type="continuous">
    <parent link="link2"/>
    <child  link="link3"/>
    <origin xyz="0 0.4 0" rpy="-1.5708 0 0"/>
    <axis   xyz="1 0 0 "/>
    <dynamics damping="1.0"/>
  </joint>

  <link name="link3"/>

  <joint name="attach-elbow" type="fixed">
    <parent link="link3"/>
    <child  link="elbow"/>
  </joint>

  <link name="elbow"/>

  <joint name="theta4" type="continuous">
    <parent link="link3"/>
    <child  link="link4"/>
    <origin xyz="0 0.4 0" rpy="0 0 0"/>
    <axis   xyz="0 1 0"/>
    <dynamics damping="0.2"/>
  </joint>

  <link name="link4"/>

  <joint name="theta5" type="continuous">
    <parent link="link4"/>
    <child  link="link5"/>
    <origin xyz="0 0 0" rpy="0 0 0"/>
    <axis   xyz="0 0 1"/>
    <dynamics damping="0.2"/>
  </joint>

  <link name="link5"/>

  <joint name="theta6" type="continuous">
    <parent link="link5"/>
    <child  link="link6"/>
    <origin xyz="0 0 0" rpy="0 0 0"/>
    <axis   xyz="1 0 0"/>
    <dynamics damping="0.2"/>
  </joint>

  <link name="link6"/>

  <joint name="final1" type="fixed">
    <parent link="link6"/>
    <child  link="tip_elbow"/>
    <origin xyz="0.1 0.0 0.2" rpy="1.5708 1.5708 0"/>
  </joint>

  <link name="tip_elbow"/>


  <!-- Second 6dof -->
    <joint name="theta7" type="continuous">
    <parent link="link6"/>
    <child  link="link7"/>
    <origin xyz="0.0 -0.6 0.4" rpy="1.5708 0 0"/>
    <axis   xyz="0 0 1"/>
    <dynamics damping="5.0"/>
  </joint>

  <link name="link7"/>

  <joint name="theta8" type="continuous">
    <parent link="link7"/>
    <child  link="link8"/>
    <origin xyz="0 0 0" rpy="0 0 0"/>
    <axis   xyz="1 0 0"/>
    <dynamics damping="5.0"/>
  </joint>

  <link name="link8"/>

  <joint name="attach-shoulder2" type="fixed">
    <parent link="link8"/>
    <child  link="shoulder2"/>
  </joint>

  <link name="shoulder2"/>

  <joint name="theta9" type="continuous">
    <parent link="link8"/>
    <child  link="link9"/>
    <origin xyz="0 0.4 0" rpy="-1.5708 0 0"/>
    <axis   xyz="1 0 0 "/>
    <dynamics damping="1.0"/>
  </joint>

  <link name="link9"/>

  <joint name="attach-elbow2" type="fixed">
    <parent link="link9"/>
    <child  link="elbow2"/>
  </joint>

  <link name="elbow2"/>

  <joint name="theta10" type="continuous">
    <parent link="link9"/>
    <child  link="link10"/>
    <origin xyz="0 0.6 0" rpy="0 0 0"/>
    <axis   xyz="0 1 0"/>
    <dynamics damping="0.2"/>
  </joint>

  <link name="link10"/>

  <joint name="theta11" type="continuous">
    <parent link="link10"/>
    <child  link="link11"/>
    <origin xyz="0 0 0" rpy="0 0 0"/>
    <axis   xyz="0 0 1"/>
    <dynamics damping="0.2"/>
  </joint>

  <link name="link11"/>

  <joint name="theta12" type="continuous">
    <parent link="link11"/>
    <child  link="link12"/>
    <origin xyz="0 0 0" rpy="0 0 0"/>
    <axis   xyz="1 0 0"/>
    <dynamics damping="0.2"/>
  </joint>

  <link name="link12"/>

  <joint name="final2" type="fixed">
    <parent link="link12"/>
    <child  link="tip_full"/>
    <origin xyz="0.0 0.0 0.1" rpy="1.5708 0 0"/>
  </joint>

  <link name="tip_full"/>


  <!-- *************************************************** -->
  <!-- ******************* RVIZ Colors ******************* -->
  <!-- *************************************************** -->

  <material name="white">    <color rgba="1.00 1.00 1.00 1"/>  </material>
  <material name="gray">     <color rgba="0.60 0.60 0.60 1"/>  </material>
  <material name="table">    <color rgba="0.85 0.77 0.77 1"/>  </material>
  <material name="black">    <color rgba="0.00 0.00 0.00 1"/>  </material>

  <material name="red">      <color rgba="1.00 0.00 0.00 1"/>  </material>
  <material name="green">    <color rgba="0.00 1.00 0.00 1"/>  </material>
  <material name="blue">     <color rgba="0.00 0.00 1.00 1"/>  </material>

  <material name="cyan">     <color rgba="0.00 1.00 1.00 1"/>  </material>
  <material name="magenta">  <color rgba="1.00 0.00 1.00 1"/>  </material>
  <material name="yellow">   <color rgba="1.00 1.00 0.00 1"/>  </material>

  <material name="orange">   <color rgba="1.00 0.65 0.00 1"/>  </material>


  <!-- *************************************************** -->
  <!-- ****** Building Blocks (Visual AND Inertial) ****** -->
  <!-- *************************************************** -->

  <!-- *** World-Fixed: Mount 1, Motor 1 *** -->

  <joint name="attach-mount1" type="fixed">
    <parent link="world"/>
    <child  link="mount1"/>
  </joint>
  <link name="mount1">
    <visual>
      <origin xyz="0 0 0.1" rpy="0 0 0"/>
      <geometry>
	<cylinder length="0.2" radius="0.02"/>
      </geometry>
      <material name="black"/>
    </visual>
    <collision>
      <origin xyz="0 0 0.1" rpy="0 0 0"/>
      <geometry>
	<cylinder length="0.2" radius="0.02"/>
      </geometry>
    </collision>
    <inertial>
      <origin xyz="0 0 0.1" rpy="0 0 0"/>
      <mass value="0.2"/>
      <inertia
        ixx="0.000687" ixy="0.0" ixz="0.0"
        iyy="0.000687" iyz="0.0"
        izz="0.000040"/>
    </inertial>
  </link>

  <joint name="attach-motor1" type="fixed">
    <parent link="world"/>
    <child  link="motor1"/>
  </joint>
  <link name="motor1">
    <visual>
      <origin xyz="0 0 0.3" rpy="0 0 0"/>
      <geometry>
	<cylinder length="0.2" radius="0.05"/>
      </geometry>
      <material name="gray"/>
    </visual>
    <collision>
      <origin xyz="0 0 0.3" rpy="0 0 0"/>
      <geometry>
	<cylinder length="0.2" radius="0.05"/>
      </geometry>
    </collision>
    <inertial>
      <origin xyz="0 0 0.3" rpy="0 0 0"/>
      <mass value="2.0"/>
      <inertia
        ixx="0.007917" ixy="0.0" ixz="0.0"
        iyy="0.007917" iyz="0.0"
        izz="0.002500"/>
    </inertial>
  </link>

  <!-- *** Motor 1 Output: Mount 2, Motor 2 *** -->

  <joint name="attach-mount2" type="fixed">
    <parent link="link1"/>
    <child  link="mount2"/>
  </joint>
  <link name="mount2">
    <visual>
      <origin xyz="0 0 -0.1" rpy="0 0 0"/>
      <geometry>
	<cylinder length="0.2" radius="0.02"/>
      </geometry>
      <material name="black"/>
    </visual>
    <collision>
      <origin xyz="0 0 -0.1" rpy="0 0 0"/>
      <geometry>
	<cylinder length="0.2" radius="0.02"/>
      </geometry>
    </collision>
    <inertial>
      <origin xyz="0 0 -0.1" rpy="0 0 0"/>
      <mass value="0.2"/>
      <inertia
        ixx="0.000687" ixy="0.0" ixz="0.0"
        iyy="0.000687" iyz="0.0"
        izz="1.000040"/>
    </inertial>
  </link>

  <joint name="attach-motor2" type="fixed">
    <parent link="link1"/>
    <child  link="motor2"/>
  </joint>
  <link name="motor2">
    <visual>
      <origin xyz="0 0 0" rpy="0 1.5708 0"/>
      <geometry>
	<cylinder length="0.2" radius="0.05"/>
      </geometry>
      <material name="gray"/>
    </visual>
    <collision>
      <origin xyz="0 0 0" rpy="0 1.5708 0"/>
      <geometry>
	<cylinder length="0.2" radius="0.05"/>
      </geometry>
    </collision>
    <inertial>
      <origin xyz="0 0 0" rpy="0 1.5708 0"/>
      <mass value="2.0"/>
      <inertia
        ixx="0.007917" ixy="0.0" ixz="0.0"
        iyy="0.007917" iyz="0.0"
        izz="0.002500"/>
    </inertial>
  </link>

  <!-- *** Motor 2 Output: Mount 3, Motor 3 *** -->

  <joint name="attach-mount3" type="fixed">
    <parent link="link2"/>
    <child  link="mount3"/>
  </joint>
  <link name="mount3">
    <visual>
      <origin xyz="0 0.1 0" rpy="1.5708 0 0"/>
      <geometry>
	<cylinder length="0.2" radius="0.02"/>
      </geometry>
      <material name="black"/>
    </visual>
    <collision>
      <origin xyz="0 0.1 0" rpy="1.5708 0 0"/>
      <geometry>
	<cylinder length="0.2" radius="0.02"/>
      </geometry>
    </collision>
    <inertial>
      <origin xyz="0 0.1 0" rpy="1.5708 0 0"/>
      <mass value="0.2"/>
      <inertia
        ixx="1.000687" ixy="0.0" ixz="0.0"
        iyy="0.000687" iyz="0.0"
        izz="0.000040"/>
    </inertial>
  </link>

  <joint name="attach-mount4" type="fixed">
    <parent link="link2"/>
    <child  link="mount4"/>
  </joint>
  <link name="mount4">
    <visual>
      <origin xyz="0 0.3 0" rpy="1.5708 0 0"/>
      <geometry>
	<cylinder length="0.2" radius="0.02"/>
      </geometry>
      <material name="black"/>
    </visual>
    <collision>
      <origin xyz="0 0.3 0" rpy="1.5708 0 0"/>
      <geometry>
	<cylinder length="0.2" radius="0.02"/>
      </geometry>
    </collision>
    <inertial>
      <origin xyz="0 0.3 0" rpy="1.5708 0 0"/>
      <mass value="0.2"/>
      <inertia
        ixx="0.000687" ixy="0.0" ixz="0.0"
        iyy="0.000687" iyz="0.0"
        izz="1.000040"/>
    </inertial>
  </link>

  <joint name="attach-motor3" type="fixed">
    <parent link="link2"/>
    <child  link="motor3"/>
  </joint>
  <link name="motor3">
    <visual>
      <origin xyz="0 0.4 0" rpy="0 1.5708 0"/>
      <geometry>
	<cylinder length="0.2" radius="0.05"/>
      </geometry>
      <material name="gray"/>
    </visual>
    <collision>
      <origin xyz="0 0.4 0" rpy="0 1.5708 0"/>
      <geometry>
	<cylinder length="0.2" radius="0.05"/>
      </geometry>
    </collision>
    <inertial>
      <origin xyz="0 0.4 0" rpy="0 1.5708 0"/>
      <mass value="2.0"/>
      <inertia
        ixx="0.007917" ixy="0.0" ixz="0.0"
        iyy="0.007917" iyz="0.0"
        izz="0.002500"/>
    </inertial>
  </link>

  <!-- *** Motor 4 Output: Mount 5, Motor 5 *** -->

  <joint name="attach-mount5" type="fixed">
    <parent link="link3"/>
    <child  link="mount5"/>
  </joint>
  <link name="mount5">
    <visual>
      <origin xyz="0 0.1 0" rpy="1.5708 0 0"/>
      <geometry>
	<cylinder length="0.2" radius="0.02"/>
      </geometry>
      <material name="black"/>
    </visual>
    <collision>
      <origin xyz="0 0.1 0" rpy="1.5708 0 0"/>
      <geometry>
	<cylinder length="0.2" radius="0.02"/>
      </geometry>
    </collision>
    <inertial>
      <origin xyz="0 0.1 0" rpy="1.5708 0 0"/>
      <mass value="0.2"/>
      <inertia
        ixx="0.500687" ixy="0.0" ixz="0.0"
        iyy="0.000687" iyz="0.0"
        izz="0.000040"/>
    </inertial>
  </link>

  <joint name="attach-motor4" type="fixed">
    <parent link="link3"/>
    <child  link="motor4"/>
  </joint>
  <link name="motor4">
    <visual>
      <origin xyz="0 0.2 0" rpy="1.5708 0 0"/>
      <geometry>
	<cylinder length="0.1" radius="0.025"/>
      </geometry>
      <material name="gray"/>
    </visual>
    <collision>
      <origin xyz="0 0.2 0" rpy="1.5708 0 0"/>
      <geometry>
	<cylinder length="0.1" radius="0.025"/>
      </geometry>
    </collision>
    <inertial>
      <origin xyz="0 0.2 0" rpy="1.5708 0 0"/>
      <mass value="1.0"/>
      <inertia
        ixx="0.000990" ixy="0.0" ixz="0.0"
        iyy="0.000990" iyz="0.0"
        izz="0.000313"/>
    </inertial>
  </link>

  <!-- *** Motor 5 Output: Mount 6, Motor 6 *** -->

  <joint name="attach-mount6" type="fixed">
    <parent link="link4"/>
    <child  link="mount6"/>
  </joint>
  <link name="mount6">
    <visual>
      <origin xyz="0 -0.1 0" rpy="1.5708 0 0"/>
      <geometry>
	<cylinder length="0.2" radius="0.01"/>
      </geometry>
      <material name="black"/>
    </visual>
    <collision>
      <origin xyz="0 -0.1 0" rpy="1.5708 0 0"/>
      <geometry>
	<cylinder length="0.2" radius="0.01"/>
      </geometry>
    </collision>
    <inertial>
      <origin xyz="0 -0.1 0" rpy="1.5708 0 0"/>
      <mass value="0.1"/>
      <inertia
        ixx="0.000336" ixy="0.0" ixz="0.0"
        iyy="0.000336" iyz="0.0"
        izz="0.500005"/>
    </inertial>
  </link>

  <joint name="attach-motor5" type="fixed">
    <parent link="link4"/>
    <child  link="motor5"/>
  </joint>
  <link name="motor5">
    <visual>
      <origin xyz="0 0 0" rpy="0 0 0"/>
      <geometry>
	<cylinder length="0.1" radius="0.025"/>
      </geometry>
      <material name="gray"/>
    </visual>
    <collision>
      <origin xyz="0 0 0" rpy="0 0 0"/>
      <geometry>
	<cylinder length="0.1" radius="0.025"/>
      </geometry>
    </collision>
    <inertial>
      <origin xyz="0 0 0" rpy="0 0 0"/>
      <mass value="1.0"/>
      <inertia
        ixx="0.000990" ixy="0.0" ixz="0.0"
        iyy="0.000990" iyz="0.0"
        izz="0.000313"/>
    </inertial>
  </link>

  <!-- *** Motor 6 Output: Motor 7 *** -->

  <joint name="attach-motor6" type="fixed">
    <parent link="link5"/>
    <child  link="motor6"/>
  </joint>
  <link name="motor6">
    <visual>
      <origin xyz="0 0 0" rpy="0 1.5708 0"/>
      <geometry>
	<cylinder length="0.1" radius="0.025"/>
      </geometry>
      <material name="gray"/>
    </visual>
    <collision>
      <origin xyz="0 0 0" rpy="0 1.5708 0"/>
      <geometry>
	<cylinder length="0.1" radius="0.025"/>
      </geometry>
    </collision>
    <inertial>
      <origin xyz="0 0 0" rpy="0 1.5708 0"/>
      <mass value="1.0"/>
      <inertia
        ixx="0.500990" ixy="0.0" ixz="0.0"
        iyy="0.000990" iyz="0.0"
        izz="0.000313"/>
    </inertial>
  </link>

  <!-- *** Drawing Sphere *** -->

  <joint name="attach-sphere" type="fixed">
    <parent link="tip_elbow"/>
    <child  link="sphere"/>
  </joint>
  <link name="sphere">
    <visual>
      <origin xyz="0 0 0" rpy="0 0 0"/>
      <geometry>
	      <sphere radius="0.01"/>
      </geometry>
      <material name="green"/>
    </visual>
    <collision>
      <origin xyz="0 0 0" rpy="0 0 0"/>
      <geometry>
	      <sphere radius="0.01"/>
      </geometry>
      <material name="green"/>
    </collision>
    <inertial>
      <origin xyz="0 0 0" rpy="0 0 0"/>
      <mass value="0.01"/>
      <inertia
        ixx="0.01" ixy="0.0" ixz="0.0"
        iyy="0.01" iyz="0.0"
        izz="0.01"/>
    </inertial>
  </link>


  <joint name="attach-cylinder" type="fixed">
    <parent link="tip_elbow"/>
    <child  link="cylinder"/>
  </joint>
  <link name="cylinder">
    <visual>
      <origin xyz="0 -0.05 0" rpy="1.5708 0 0"/>
      <geometry>
	      <cylinder length="0.1" radius="0.01"/>
      </geometry>
      <material name="gray"/>
    </visual>
    <collision>
      <origin xyz="0 -0.05 0" rpy="1.5708 0 0"/>
      <geometry>
	      <cylinder length="0.1" radius="0.01"/>
      </geometry>
    </collision>
    <inertial>
      <origin xyz="0 0 0" rpy="0 1.5708 0"/>
      <mass value="0.01"/>
      <inertia
        ixx="0.500990" ixy="0.0" ixz="0.0"
        iyy="0.000990" iyz="0.0"
        izz="0.000313"/>
    </inertial>
  </link>


  <!-- Second 6dof -->
  <!-- *** World-Fixed: Mount 1, Motor 1 *** -->
  <joint name="attach-mountl" type="fixed">
    <parent link="link6"/>
    <child  link="mountl"/>
  </joint>
  <link name="mountl">
    <visual>
      <origin xyz="0 0.0 0.2" rpy="0 0 0"/>
      <geometry>
	<cylinder length="0.4" radius="0.02"/>
      </geometry>
      <material name="black"/>
    </visual>
    <collision>
      <origin xyz="0 -0.1 0.4" rpy="1.5708 0 0"/>
      <geometry>
	<cylinder length="0.2" radius="0.02"/>
      </geometry>
    </collision>
    <inertial>
      <origin xyz="0 -0.1 0.4" rpy="1.5708 0 0"/>
      <mass value="0.1"/>
      <inertia
        ixx="0.000687" ixy="0.0" ixz="0.0"
        iyy="0.000687" iyz="0.0"
        izz="0.000040"/>
    </inertial>
  </link>


  <joint name="attach-mount7" type="fixed">
    <parent link="link6"/>
    <child  link="mount7"/>
  </joint>
  <link name="mount7">
    <visual>
      <origin xyz="0 -0.1 0.4" rpy="1.5708 0 0"/>
      <geometry>
	<cylinder length="0.2" radius="0.02"/>
      </geometry>
      <material name="black"/>
    </visual>
    <collision>
      <origin xyz="0 -0.1 0.4" rpy="1.5708 0 0"/>
      <geometry>
	<cylinder length="0.2" radius="0.02"/>
      </geometry>
    </collision>
    <inertial>
      <origin xyz="0 -0.1 0.4" rpy="1.5708 0 0"/>
      <mass value="0.1"/>
      <inertia
        ixx="0.000687" ixy="0.0" ixz="0.0"
        iyy="0.000687" iyz="0.0"
        izz="0.000040"/>
    </inertial>
  </link>

  <joint name="attach-motor7" type="fixed">
    <parent link="link6"/>
    <child  link="motor7"/>
  </joint>
  <link name="motor7">
    <visual>
      <origin xyz="0 -0.3 0.4" rpy="1.5708 0 0"/>
      <geometry>
	<cylinder length="0.2" radius="0.05"/>
      </geometry>
      <material name="gray"/>
    </visual>
    <collision>
      <origin xyz="0 -0.3 0.4" rpy="1.5708 0 0"/>
      <geometry>
	<cylinder length="0.2" radius="0.05"/>
      </geometry>
    </collision>
    <inertial>
      <origin xyz="0 -0.3 0.4" rpy="1.5708 0 0"/>
      <mass value="0.1"/>
      <inertia
        ixx="0.007917" ixy="0.0" ixz="0.0"
        iyy="0.007917" iyz="0.0"
        izz="0.002500"/>
    </inertial>
  </link>

  <!-- *** Motor 1 Output: Mount 2, Motor 2 *** -->

  <joint name="attach-mount8" type="fixed">
    <parent link="link7"/>
    <child  link="mount8"/>
  </joint>
  <link name="mount8">
    <visual>
      <origin xyz="0 0 -0.1" rpy="0 0 0"/>
      <geometry>
	<cylinder length="0.2" radius="0.02"/>
      </geometry>
      <material name="black"/>
    </visual>
    <collision>
      <origin xyz="0 0 -0.1" rpy="0 0 0"/>
      <geometry>
	<cylinder length="0.2" radius="0.02"/>
      </geometry>
    </collision>
    <inertial>
      <origin xyz="0 0 -0.1" rpy="0 0 0"/>
      <mass value="0.1"/>
      <inertia
        ixx="0.000687" ixy="0.0" ixz="0.0"
        iyy="0.000687" iyz="0.0"
        izz="1.000040"/>
    </inertial>
  </link>

  <joint name="attach-motor8" type="fixed">
    <parent link="link7"/>
    <child  link="motor8"/>
  </joint>
  <link name="motor8">
    <visual>
      <origin xyz="0 0 0" rpy="0 1.5708 0"/>
      <geometry>
	<cylinder length="0.2" radius="0.05"/>
      </geometry>
      <material name="gray"/>
    </visual>
    <collision>
      <origin xyz="0 0 0" rpy="0 1.5708 0"/>
      <geometry>
	<cylinder length="0.2" radius="0.05"/>
      </geometry>
    </collision>
    <inertial>
      <origin xyz="0 0 0" rpy="0 1.5708 0"/>
      <mass value="0.1"/>
      <inertia
        ixx="0.007917" ixy="0.0" ixz="0.0"
        iyy="0.007917" iyz="0.0"
        izz="0.002500"/>
    </inertial>
  </link>

  <!-- *** Motor 2 Output: Mount 3, Motor 3 *** -->

  <joint name="attach-mount9" type="fixed">
    <parent link="link8"/>
    <child  link="mount9"/>
  </joint>
  <link name="mount9">
    <visual>
      <origin xyz="0 0.1 0" rpy="1.5708 0 0"/>
      <geometry>
	<cylinder length="0.2" radius="0.02"/>
      </geometry>
      <material name="black"/>
    </visual>
    <collision>
      <origin xyz="0 0.1 0" rpy="1.5708 0 0"/>
      <geometry>
	<cylinder length="0.2" radius="0.02"/>
      </geometry>
    </collision>
    <inertial>
      <origin xyz="0 0.1 0" rpy="1.5708 0 0"/>
      <mass value="0.1"/>
      <inertia
        ixx="1.000687" ixy="0.0" ixz="0.0"
        iyy="0.000687" iyz="0.0"
        izz="0.000040"/>
    </inertial>
  </link>

  <joint name="attach-mount10" type="fixed">
    <parent link="link8"/>
    <child  link="mount10"/>
  </joint>
  <link name="mount10">
    <visual>
      <origin xyz="0 0.3 0" rpy="1.5708 0 0"/>
      <geometry>
	<cylinder length="0.2" radius="0.02"/>
      </geometry>
      <material name="black"/>
    </visual>
    <collision>
      <origin xyz="0 0.3 0" rpy="1.5708 0 0"/>
      <geometry>
	<cylinder length="0.2" radius="0.02"/>
      </geometry>
    </collision>
    <inertial>
      <origin xyz="0 0.3 0" rpy="1.5708 0 0"/>
      <mass value="0.1"/>
      <inertia
        ixx="0.000687" ixy="0.0" ixz="0.0"
        iyy="0.000687" iyz="0.0"
        izz="1.000040"/>
    </inertial>
  </link>

  <joint name="attach-motor9" type="fixed">
    <parent link="link8"/>
    <child  link="motor9"/>
  </joint>
  <link name="motor9">
    <visual>
      <origin xyz="0 0.4 0" rpy="0 1.5708 0"/>
      <geometry>
	<cylinder length="0.2" radius="0.05"/>
      </geometry>
      <material name="gray"/>
    </visual>
    <collision>
      <origin xyz="0 0.4 0" rpy="0 1.5708 0"/>
      <geometry>
	<cylinder length="0.2" radius="0.05"/>
      </geometry>
    </collision>
    <inertial>
      <origin xyz="0 0.4 0" rpy="0 1.5708 0"/>
      <mass value="0.1"/>
      <inertia
        ixx="0.007917" ixy="0.0" ixz="0.0"
        iyy="0.007917" iyz="0.0"
        izz="0.002500"/>
    </inertial>
  </link>

  <!-- *** Motor 4 Output: Mount 5, Motor 5 *** -->

  <joint name="attach-mount11" type="fixed">
    <parent link="link9"/>
    <child  link="mount11"/>
  </joint>
  <link name="mount11">
    <visual>
      <origin xyz="0 0.1 0" rpy="1.5708 0 0"/>
      <geometry>
	<cylinder length="0.2" radius="0.02"/>
      </geometry>
      <material name="black"/>
    </visual>
    <collision>
      <origin xyz="0 0.1 0" rpy="1.5708 0 0"/>
      <geometry>
	<cylinder length="0.2" radius="0.02"/>
      </geometry>
    </collision>
    <inertial>
      <origin xyz="0 0.1 0" rpy="1.5708 0 0"/>
      <mass value="0.1"/>
      <inertia
        ixx="0.500687" ixy="0.0" ixz="0.0"
        iyy="0.000687" iyz="0.0"
        izz="0.000040"/>
    </inertial>
  </link>

  <joint name="attach-motor10" type="fixed">
    <parent link="link9"/>
    <child  link="motor10"/>
  </joint>
  <link name="motor10">
    <visual>
      <origin xyz="0 0.2 0" rpy="1.5708 0 0"/>
      <geometry>
	<cylinder length="0.1" radius="0.025"/>
      </geometry>
      <material name="gray"/>
    </visual>
    <collision>
      <origin xyz="0 0.2 0" rpy="1.5708 0 0"/>
      <geometry>
	<cylinder length="0.1" radius="0.025"/>
      </geometry>
    </collision>
    <inertial>
      <origin xyz="0 0.2 0" rpy="1.5708 0 0"/>
      <mass value="0.1"/>
      <inertia
        ixx="0.000990" ixy="0.0" ixz="0.0"
        iyy="0.000990" iyz="0.0"
        izz="0.000313"/>
    </inertial>
  </link>

  <!-- *** Motor 5 Output: Mount 6, Motor 6 *** -->

  <joint name="attach-mount12" type="fixed">
    <parent link="link10"/>
    <child  link="mount12"/>
  </joint>
  <link name="mount12">
    <visual>
      <origin xyz="0 -0.2 0" rpy="1.5708 0 0"/>
      <geometry>
	<cylinder length="0.4" radius="0.01"/>
      </geometry>
      <material name="black"/>
    </visual>
    <collision>
      <origin xyz="0 -0.2 0" rpy="1.5708 0 0"/>
      <geometry>
	<cylinder length="0.4" radius="0.01"/>
      </geometry>
    </collision>
    <inertial>
      <origin xyz="0 -0.2 0" rpy="1.5708 0 0"/>
      <mass value="0.1"/>
      <inertia
        ixx="0.000336" ixy="0.0" ixz="0.0"
        iyy="0.000336" iyz="0.0"
        izz="0.500005"/>
    </inertial>
  </link>

  <joint name="attach-motor11" type="fixed">
    <parent link="link10"/>
    <child  link="motor11"/>
  </joint>
  <link name="motor11">
    <visual>
      <origin xyz="0 0 0" rpy="0 0 0"/>
      <geometry>
	<cylinder length="0.1" radius="0.025"/>
      </geometry>
      <material name="gray"/>
    </visual>
    <collision>
      <origin xyz="0 0 0" rpy="0 0 0"/>
      <geometry>
	<cylinder length="0.1" radius="0.025"/>
      </geometry>
    </collision>
    <inertial>
      <origin xyz="0 0 0" rpy="0 0 0"/>
      <mass value="0.1"/>
      <inertia
        ixx="0.000990" ixy="0.0" ixz="0.0"
        iyy="0.000990" iyz="0.0"
        izz="0.000313"/>
    </inertial>
  </link>

  <!-- *** Motor 6 Output: Motor 7 *** -->

  <joint name="attach-motor12" type="fixed">
    <parent link="link11"/>
    <child  link="motor12"/>
  </joint>
  <link name="motor12">
    <visual>
      <origin xyz="0 0 0" rpy="0 1.5708 0"/>
      <geometry>
	<cylinder length="0.1" radius="0.025"/>
      </geometry>
      <material name="gray"/>
    </visual>
    <collision>
      <origin xyz="0 0 0" rpy="0 1.5708 0"/>
      <geometry>
	<cylinder length="0.1" radius="0.025"/>
      </geometry>
    </collision>
    <inertial>
      <origin xyz="0 0 0" rpy="0 1.5708 0"/>
      <mass value="0.1"/>
      <inertia
        ixx="0.500990" ixy="0.0" ixz="0.0"
        iyy="0.000990" iyz="0.0"
        izz="0.000313"/>
    </inertial>
  </link>

  <!-- *** Drawing Sphere *** -->

  <joint name="attach-sphere2" type="fixed">
    <parent link="tip_full"/>
    <child  link="sphere2"/>
  </joint>
  <link name="sphere2">
    <visual>
      <origin xyz="0 0 0" rpy="0 0 0"/>
      <geometry>
	      <sphere radius="0.01"/>
      </geometry>
      <material name="green"/>
    </visual>
    <collision>
      <origin xyz="0 0 0" rpy="0 0 0"/>
      <geometry>
	      <sphere radius="0.01"/>
      </geometry>
      <material name="green"/>
    </collision>
    <inertial>
      <origin xyz="0 0 0" rpy="0 0 0"/>
      <mass value="0.1"/>
      <inertia
        ixx="0.01" ixy="0.0" ixz="0.0"
        iyy="0.01" iyz="0.0"
        izz="0.01"/>
    </inertial>
  </link>


  <joint name="attach-cylinder2" type="fixed">
    <parent link="tip_full"/>
    <child  link="cylinder2"/>
  </joint>
  <link name="cylinder2">
    <visual>
      <origin xyz="0 -0.05 0" rpy="1.5708 0 0"/>
      <geometry>
	      <cylinder length="0.1" radius="0.01"/>
      </geometry>
      <material name="gray"/>
    </visual>
    <collision>
      <origin xyz="0 -0.05 0" rpy="1.5708 0 0"/>
      <geometry>
	      <cylinder length="0.1" radius="0.01"/>
      </geometry>
    </collision>
    <inertial>
      <origin xyz="0 0 0" rpy="0 1.5708 0"/>
      <mass value="0.1"/>
      <inertia
        ixx="0.500990" ixy="0.0" ixz="0.0"
        iyy="0.000990" iyz="0.0"
        izz="0.000313"/>
    </inertial>
  </link>

  <!-- *************************************************** -->
  <!-- ******************* Gazebo Colors ***************** -->
  <!-- *************************************************** -->

  <gazebo reference="motor1"> <material>Gazebo/Gray</material>  </gazebo>
  <gazebo reference="motor2"> <material>Gazebo/Gray</material>  </gazebo>
  <gazebo reference="motor3"> <material>Gazebo/Gray</material>  </gazebo>
  <gazebo reference="motor4"> <material>Gazebo/Gray</material>  </gazebo>
  <gazebo reference="motor5"> <material>Gazebo/Gray</material>  </gazebo>
  <gazebo reference="motor6"> <material>Gazebo/Gray</material>  </gazebo>
  <gazebo reference="motor7"> <material>Gazebo/Gray</material>  </gazebo>
  <gazebo reference="motor8"> <material>Gazebo/Gray</material>  </gazebo>
  <gazebo reference="motor9"> <material>Gazebo/Gray</material>  </gazebo>
  <gazebo reference="motor10"> <material>Gazebo/Gray</material>  </gazebo>
  <gazebo reference="motor11"> <material>Gazebo/Gray</material>  </gazebo>
  <gazebo reference="motor12"> <material>Gazebo/Gray</material>  </gazebo>

  <gazebo reference="mount1">   <material>Gazebo/Black</material> </gazebo>
  <gazebo reference="mount2">   <material>Gazebo/Black</material> </gazebo>
  <gazebo reference="mount3">   <material>Gazebo/Black</material> </gazebo>
  <gazebo reference="mount4">   <material>Gazebo/Black</material> </gazebo>
  <gazebo reference="mount5">   <material>Gazebo/Black</material> </gazebo>
  <gazebo reference="mount6">   <material>Gazebo/Black</material> </gazebo>
  <gazebo reference="mount7">   <material>Gazebo/Black</material> </gazebo>
  <gazebo reference="mount8">   <material>Gazebo/Black</material> </gazebo>
  <gazebo reference="mount9">   <material>Gazebo/Black</material> </gazebo>
  <gazebo reference="mount10">   <material>Gazebo/Black</material> </gazebo>
  <gazebo reference="mount11">   <material>Gazebo/Black</material> </gazebo>
  <gazebo reference="mount12">   <material>Gazebo/Black</material> </gazebo>
  <gazebo reference="mountl">   <material>Gazebo/Black</material> </gazebo>

  <gazebo reference="sphere">  <material>Gazebo/Green</material>  </gazebo>

  
  <!-- *************************************************** -->
  <!-- ************** Gazebo Transmissions *************** -->
  <!-- *************************************************** -->

  <transmission name="trans1">
    <type>transmission_interface/SimpleTransmission</type>
    <joint name="theta1">
      <hardwareInterface>hardware_interface/EffortJointInterface</hardwareInterface>
    </joint>
    <actuator name="motor1">
      <mechanicalReduction>1</mechanicalReduction>
      <hardwareInterface>hardware_interface/EffortJointInterface</hardwareInterface>
    </actuator>
  </transmission>
  
  <transmission name="trans2">
    <type>transmission_interface/SimpleTransmission</type>
    <joint name="theta2">
      <hardwareInterface>hardware_interface/EffortJointInterface</hardwareInterface>
    </joint>
    <actuator name="motor2">
      <mechanicalReduction>1</mechanicalReduction>
      <hardwareInterface>hardware_interface/EffortJointInterface</hardwareInterface>
    </actuator>
  </transmission>
  
  <transmission name="trans3">
    <type>transmission_interface/SimpleTransmission</type>
    <joint name="theta3">
      <hardwareInterface>hardware_interface/EffortJointInterface</hardwareInterface>
    </joint>
    <actuator name="motor3">
      <mechanicalReduction>1</mechanicalReduction>
      <hardwareInterface>hardware_interface/EffortJointInterface</hardwareInterface>
    </actuator>
  </transmission>
  
  <transmission name="trans4">
    <type>transmission_interface/SimpleTransmission</type>
    <joint name="theta4">
      <hardwareInterface>hardware_interface/EffortJointInterface</hardwareInterface>
    </joint>
    <actuator name="motor4">
      <mechanicalReduction>1</mechanicalReduction>
      <hardwareInterface>hardware_interface/EffortJointInterface</hardwareInterface>
    </actuator>
  </transmission>
  
  <transmission name="trans5">
    <type>transmission_interface/SimpleTransmission</type>
    <joint name="theta5">
      <hardwareInterface>hardware_interface/EffortJointInterface</hardwareInterface>
    </joint>
    <actuator name="motor5">
      <mechanicalReduction>1</mechanicalReduction>
      <hardwareInterface>hardware_interface/EffortJointInterface</hardwareInterface>
    </actuator>
  </transmission>
  
  <transmission name="trans6">
    <type>transmission_interface/SimpleTransmission</type>
    <joint name="theta6">
      <hardwareInterface>hardware_interface/EffortJointInterface</hardwareInterface>
    </joint>
    <actuator name="motor6">
      <mechanicalReduction>1</mechanicalReduction>
      <hardwareInterface>hardware_interface/EffortJointInterface</hardwareInterface>
    </actuator>
  </transmission>

  <!-- Second 6dof -->

    <transmission name="trans7">
    <type>transmission_interface/SimpleTransmission</type>
    <joint name="theta7">
      <hardwareInterface>hardware_interface/EffortJointInterface</hardwareInterface>
    </joint>
    <actuator name="motor7">
      <mechanicalReduction>1</mechanicalReduction>
      <hardwareInterface>hardware_interface/EffortJointInterface</hardwareInterface>
    </actuator>
  </transmission>
  
  <transmission name="trans8">
    <type>transmission_interface/SimpleTransmission</type>
    <joint name="theta8">
      <hardwareInterface>hardware_interface/EffortJointInterface</hardwareInterface>
    </joint>
    <actuator name="motor8">
      <mechanicalReduction>1</mechanicalReduction>
      <hardwareInterface>hardware_interface/EffortJointInterface</hardwareInterface>
    </actuator>
  </transmission>
  
  <transmission name="trans9">
    <type>transmission_interface/SimpleTransmission</type>
    <joint name="theta9">
      <hardwareInterface>hardware_interface/EffortJointInterface</hardwareInterface>
    </joint>
    <actuator name="motor9">
      <mechanicalReduction>1</mechanicalReduction>
      <hardwareInterface>hardware_interface/EffortJointInterface</hardwareInterface>
    </actuator>
  </transmission>
  
  <transmission name="trans10">
    <type>transmission_interface/SimpleTransmission</type>
    <joint name="theta10">
      <hardwareInterface>hardware_interface/EffortJointInterface</hardwareInterface>
    </joint>
    <actuator name="motor10">
      <mechanicalReduction>1</mechanicalReduction>
      <hardwareInterface>hardware_interface/EffortJointInterface</hardwareInterface>
    </actuator>
  </transmission>
  
  <transmission name="trans11">
    <type>transmission_interface/SimpleTransmission</type>
    <joint name="theta11">
      <hardwareInterface>hardware_interface/EffortJointInterface</hardwareInterface>
    </joint>
    <actuator name="motor11">
      <mechanicalReduction>1</mechanicalReduction>
      <hardwareInterface>hardware_interface/EffortJointInterface</hardwareInterface>
    </actuator>
  </transmission>
  
  <transmission name="trans12">
    <type>transmission_interface/SimpleTransmission</type>
    <joint name="theta12">
      <hardwareInterface>hardware_interface/EffortJointInterface</hardwareInterface>
    </joint>
    <actuator name="motor12">
      <mechanicalReduction>1</mechanicalReduction>
      <hardwareInterface>hardware_interface/EffortJointInterface</hardwareInterface>
    </actuator>
  </transmission>

  
  <!-- *************************************************** -->
  <!-- *************** Gazebo Controllers **************** -->
  <!-- *************************************************** -->

  <gazebo>
    <plugin name="gazebo_ros_control" filename="libgazebo_ros_control.so">
      <robotNamespace>/twelvedof</robotNamespace>
      <robotSimType>gazebo_ros_control/DefaultRobotHWSim</robotSimType>
    </plugin>
  </gazebo>

</robot>
